Workbook
Name IQ_CH: 110000
Name IQ_CQ: 5000
Name IQ_CY: 10000
Name IQ_DAILY: 500000
Name IQ_FH: 100000
Name IQ_FQ: 500
Name IQ_FY: 1000
Name IQ_LTM: 2000
Name IQ_MONTH: 15000
Name IQ_NTM: 6000
Name IQ_WEEK: 50000
Name IQ_YTD: 3000

Sheet 投资观点
A1: 顺络电子 (002138.SZ) — 投资观点与核心假设 | 买方模型 v2 (行业假设联动版) 2026-06-11
A2: 概率加权 P/E(FY2027E)| 实际值: Wind同根双源对账零差异 + 2026Q1业绩说明会 | 收入YoY/AI额/分线GM ◀绿链6个行业假设sheet(QPM v2.6) | 现价55.83元(市值450亿)
A4: 核心结论
A5: 概率加权目标价 63.1元,较现价 55.83元 +13.0%:Base(55%概率,61.5元/+10.1%)= FY2027E 归母16.5亿×30x = 495亿市值,与QPM v2.6情景引擎Base 495亿精确咬合——本模型三表引擎在装入QPM行业假设(机柜×颗数×ASP×份额、NEV量价、钽电容总盘)后,独立复算出与QPM相同的盈利,形成双引擎交叉验证。现价对应 40.7x FY26E / 27.3x FY27E PE。赔率结构:Bull 89.6元(+61%,25%) / Bear 34.4元(−38%,20%),期望收益+13%为正但集中在AI兑现:钽电容存储订单(26年底窗口)与VR200 ramp(4Q26)是未来两个季度的胜负手。FY26E 归母11.1亿仍低于一致预期13.1亿——分歧在银价下的毛利率修复斜率(本模型FY26 GM 35.2% vs 卖方36.6%+,Q1'26实际32%站在我们一边);2Q26若调价兑现(QPM隐含math: NP beat概率55-65%),Base上修路径清晰。
A7: 🐂 牛市观点(Bull → 89.6元,+61%,概率25%)
A8: ① 钽电容份额故事兑现:行业总盘220→293→340亿(假设_钽电容,海外四大90%+且基本不扩产、三轮涨价高端累计65%),顺络渗透仅0.8%→2.6%(Base);Bull=存储原厂订单Q4落地+NV 8规格提前批量+国庆涨价25%全落地——卖方SOTP隐含存储钽20%份额 vs 本模型2.6%,这一裂口就是Bull的空间(QPM Bull NP27 20.7亿)。
A9: ② AI电感量价双击:行业金额40→70→95亿(假设_AI电感:NV机柜7.5→15万柜×颗数4500→6000+TPU V7单芯片$100),顺络份额13%→17%(国产算力TLVR一供独供+TLVR 8条线H2投产+泰国6条2027);TLVR四相$2单价(两相$1的2倍)+村田二轮涨价→新兴线GM 38%→42%(JPM给国巨电感26.8%→46%佐证)。
A10: ③ 汽车content加速:NEV盘子82.5→105→130亿×份额20.8%→20.0%(假设_汽车储能),车规电感+50%指引、域控板用量+30-40%、电池客户(BMS)成第一大客户;Base已含+29%/+29%/+24%,800V加速则向中金+37.5%收敛。
A11: ④ 估值锚共振:Base 30x 27E vs 国巨链卖方目标23-35x(27/28E)、A股被动件AI周期溢价;若2H26业绩逐季加速(QPM季度路径4Q26 YoY+36%),30x在Accel-Up期有支撑,Bull 35x对应724亿(QPM)。
A13: 🐻 熊市观点(Bear → 34.4元,−38%,概率20%=QPM Bear15%+Tail5%)
A14: ① 银价传导失败:银占叠层BOM~30%,调价'仅覆盖成本不加价'且直接客户逐户谈判;若GM修复止步34%,FY26归母<10亿,现价40.7x FY26E直接暴露;Q3'26分红季现金水位仅0.3亿(Base),融资依赖度上升。
A15: ② AI期权折戟链:VR200推迟2季+国产算力27年库存消化+乾坤/村田挤份额(Rubin电感单价$0.3-0.4不可阻挡的量增价减)+钽涨价被大客户拒绝+存储订单流空(QPM Bear驱动);钽量产know-how可靠性问题未彻底解决(苹果两三年未放量/海力士试跑出过问题/NV尚未送样——渠道专家口径,与段子'已获订单'冲突)。
... A26: 注:v2变更——Drivers黄底收入YoY/AI绝对额/分线GM全部改为绿链后部6个行业假设sheet(假设_手机电感/消费AIoT/汽车储能/AI电感/钽电容/其他),行业假设=QPM v2.6(机柜/TPU/NEV/钽总盘/份额/GM路径);费用率/Capex/营运资本/债务/分红仍为Drivers本页黄底(公司层假设)。模型经pycel全表校验:公式错误0、BS 22列平衡|chk|<0.001、Drivers↔行业假设年度勾稽10/10精确、Q1'26归母勾稽差+0.3mn。三表引擎独立复算FY27E归母16.5亿=QPM Base,双引擎互证。

Sheet Drivers
A1: 顺络电子 (002138.SZ) — P&L 驱动页 | 分应用 量×率 STP
A2: 单位:人民币百万元。FY23-FY25A+2025季度=实际(Wind同根·中金/国信模型dump,双源对账零差异);Q1'26A=业绩说明会锚;Q2'26E起收入YoY/AI额/分线GM=绿链后部6个行业假设sheet(QPM v2.6行业STP),费用率/Capex/WC/债务/分红仍为本页黄底(公司层假设)。
A3: 图例: 蓝=硬编码实际值 | 黑=公式 | 绿=跨表链接(行业假设见 假设_手机电感/消费AIoT/汽车储能/AI电感/钽电容/其他) | 黄底=可修改假设。Q1'26A列(I列)分应用为黄底校准,勾稽至披露锚(营收16.84亿/归母1.78亿/毛利率32%);2025季度列仅损益。
B5: FY2023A | C5: FY2024A | D5: Q1'25A | E5: Q2'25A | F5: Q3'25A | G5: Q4'25A | H5: FY2025A | I5: Q1'26A | J5: Q2'26E | K5: Q3'26E | L5: Q4'26E | M5: FY2026E | N5: Q1'27E | O5: Q2'27E | P5: Q3'27E | Q5: Q4'27E | R5: FY2027E | S5: Q1'28E | T5: Q2'28E | U5: Q3'28E | V5: Q4'28E | W5: FY2028E
A6: 一、分应用收入引擎 (Rmb mn) — 预测YoY/AI绝对额 ◀绿链后部行业假设sheet(QPM v2.6); I列=Q1'26黄底校准
A7: 手机通讯 | B7: 1713.74 | C7: 2005.08 | D7: 423.61 | E7: 511.41 | F7: 524.27 | G7: 525.74 | H7: 1985.03 | I7: =D7*(1+I8) -> 423.61 | J7: =E7*(1+J8) -> 521.61989 | K7: =F7*(1+K8) -> 534.73663 | L7: =G7*(1+L8) -> 536.23598 | M7: =SUM(I7:L7) -> 2016.2025 | N7: =I7*(1+N8) -> 429.59676 | O7: =J7*(1+O8) -> 528.99179 | P7: =K7*(1+P8) -> 542.29391 | Q7: =L7*(1+Q8) -> 543.81444 | R7: =SUM(N7:Q7) -> 2044.6969 | S7: =N7*(1+S8) -> 433.43643 | T7: =O7*(1+T8) -> 533.71985 | U7: =P7*(1+U8) -> 547.14086 | V7: =Q7*(1+V8) -> 548.67499 | W7: =SUM(S7:V7) -> 2062.9721
A8: YoY | C8: =C7/B7-1 -> 0.17000245 | H8: =H7/C7-1 -> -0.009999601 | I8: 0 | J8: =业务1_手机电感!$D$12 -> 0.019964199 | K8: =业务1_手机电感!$D$12 -> 0.019964199 | L8: =业务1_手机电感!$D$12 -> 0.019964199 | M8: =M7/H7-1 -> 0.015703793 | N8: =业务1_手机电感!$E$12 -> 0.014132705 | O8: =业务1_手机电感!$E$12 -> 0.014132705 | P8: =业务1_手机电感!$E$12 -> 0.014132705 | Q8: =业务1_手机电感!$E$12 -> 0.014132705 | R8: =R7/M7-1 -> 0.014132705 | S8: =业务1_手机电感!$F$12 -> 0.0089378685 | T8: =业务1_手机电感!$F$12 -> 0.0089378685 | U8: =业务1_手机电感!$F$12 -> 0.0089378685 | V8: =业务1_手机电感!$F$12 -> 0.0089378685 | W8: =W7/R7-1 -> 0.0089378685
A9: 消费电子(非手机) | B9: 1234.9 | C9: 1506.58 | D9: 357.88 | E9: 415.93 | F9: 383.56 | G9: 334.15 | H9: 1491.52 | I9: =D9*(1+I10) -> 390.0892 | J9: =E9*(1+J10) -> 430.21729 | K9: =F9*(1+K10) -> 396.73538 | L9: =G9*(1+L10) -> 345.62813 | M9: =SUM(I9:L9) -> 1562.67 | N9: =I9*(1+N10) -> 409.16342 | O9: =J9*(1+O10) -> 451.25366 | P9: =K9*(1+P10) -> 416.13458 | Q9: =L9*(1+Q10) -> 362.52834 | R9: =SUM(N9:Q9) -> 1639.08 | S9: =N9*(1+S10) -> 424.72311 | T9: =O9*(1+T10) -> 468.41395 | U9: =P9*(1+U10) -> 431.95936 | V9: =Q9*(1+V10) -> 376.31458 | W9: =SUM(S9:V9) -> 1701.411
A10: YoY | C10: =C9/B9-1 -> 0.22000162 | H10: =H9/C9-1 -> -0.0099961502 | I10: 0.09 | J10: =业务2_消费AIoT!$D$8 -> 0.034350235 | K10: =业务2_消费AIoT!$D$8 -> 0.034350235 | L10: =业务2_消费AIoT!$D$8 -> 0.034350235 | M10: =M9/H9-1 -> 0.047703014 | N10: =业务2_消费AIoT!$E$8 -> 0.04889708 | O10: =业务2_消费AIoT!$E$8 -> 0.04889708 | P10: =业务2_消费AIoT!$E$8 -> 0.04889708 | Q10: =业务2_消费AIoT!$E$8 -> 0.04889708 | R10: =R9/M9-1 -> 0.04889708 | S10: =业务2_消费AIoT!$F$8 -> 0.03802804 | T10: =业务2_消费AIoT!$F$8 -> 0.03802804 | U10: =业务2_消费AIoT!$F$8 -> 0.03802804 | V10: =业务2_消费AIoT!$F$8 -> 0.03802804 | W10: =W9/R9-1 -> 0.03802804
A11: 汽车电子及储能 | B11: 681.17 | C11: 1104.16 | D11: 314.4 | E11: 326.97 | F11: 412.44 | G11: 471 | H11: 1524.81 | I11: =D11*(1+I12) -> 393.9432 | J11: =E11*(1+J12) -> 424.66223 | K11: =F11*(1+K12) -> 535.66899 | L11: =G11*(1+L12) -> 611.72557 | M11: =SUM(I11:L11) -> 1966 | N11: =I11*(1+N12) -> 507.46737 | O11: =J11*(1+O12) -> 547.03883 | P11: =K11*(1+P12) -> 690.03485 | Q11: =L11*(1+Q12) -> 788.00895 | R11: =SUM(N11:Q11) -> 2532.55 | S11: =N11*(1+S12) -> 631.45127 | T11: =O11*(1+T12) -> 680.69079 | U11: =P11*(1+U12) -> 858.62345 | V11: =Q11*(1+V12) -> 980.53449 | W11: =SUM(S11:V11) -> 3151.3
A12: YoY | C12: =C11/B11-1 -> 0.62097567 | H12: =H11/C11-1 -> 0.38096834 | I12: 0.253 | J12: =业务3_汽车储能!$D$15 -> 0.29878041 | K12: =业务3_汽车储能!$D$15 -> 0.29878041 | L12: =业务3_汽车储能!$D$15 -> 0.29878041 | M12: =M11/H11-1 -> 0.28934097 | N12: =业务3_汽车储能!$E$15 -> 0.28817396 | O12: =业务3_汽车储能!$E$15 -> 0.28817396 | P12: =业务3_汽车储能!$E$15 -> 0.28817396 | Q12: =业务3_汽车储能!$E$15 -> 0.28817396 | R12: =R11/M11-1 -> 0.28817396 | S12: =业务3_汽车储能!$F$15 -> 0.24431897 | T12: =业务3_汽车储能!$F$15 -> 0.24431897 | U12: =业务3_汽车储能!$F$15 -> 0.24431897 | V12: =业务3_汽车储能!$F$15 -> 0.24431897 | W12: =W11/R11-1 -> 0.24431897
A13: 大工业(基站/ICT/服务器电源) | B13: 504.04 | C13: 504.04 | D13: 116.86 | E13: 141.08 | F13: 144.62 | G13: 101.48 | H13: 504.04 | I13: =D13*(1+I14) -> 122.00184 | J13: =E13*(1+J14) -> 141.37812 | K13: =F13*(1+K14) -> 144.9256 | L13: =G13*(1+L14) -> 101.69444 | M13: =SUM(I13:L13) -> 510 | N13: =I13*(1+N14) -> 124.39403 | O13: =J13*(1+O14) -> 144.15024 | P13: =K13*(1+P14) -> 147.76728 | Q13: =L13*(1+Q14) -> 103.68845 | R13: =SUM(N13:Q13) -> 520 | S13: =N13*(1+S14) -> 126.78623 | T13: =O13*(1+T14) -> 146.92236 | U13: =P13*(1+U14) -> 150.60896 | V13: =Q13*(1+V14) -> 105.68246 | W13: =SUM(S13:V13) -> 530
A14: YoY | C14: =C13/B13-1 -> 0 | H14: =H13/C13-1 -> 0 | I14: 0.044 | J14: =其他业务!$D$5 -> 0.0021131257 | K14: =其他业务!$D$5 -> 0.0021131257 | L14: =其他业务!$D$5 -> 0.0021131257 | M14: =M13/H13-1 -> 0.011824458 | N14: =其他业务!$E$5 -> 0.019607843 | O14: =其他业务!$E$5 -> 0.019607843 | P14: =其他业务!$E$5 -> 0.019607843 | Q14: =其他业务!$E$5 -> 0.019607843 | R14: =R13/M13-1 -> 0.019607843 | S14: =其他业务!$F$5 -> 0.019230769 | T14: =其他业务!$F$5 -> 0.019230769 | U14: =其他业务!$F$5 -> 0.019230769 | V14: =其他业务!$F$5 -> 0.019230769 | W14: =W13/R13-1 -> 0.019230769
A15: 特种(贵阳·军工) | B15: 554.45 | C15: 388.11 | D15: 102.25 | E15: 187.93 | F15: 112.38 | G15: 103.93 | H15: 506.49 | I15: =D15*(1+I16) -> 162.63885 | J15: =E15*(1+J16) -> 206.58221 | K15: =F15*(1+K16) -> 123.53381 | L15: =G15*(1+L16) -> 114.24514 | M15: =SUM(I15:L15) -> 607 | N15: =I15*(1+N16) -> 187.02128 | O15: =J15*(1+O16) -> 237.55252 | P15: =K15*(1+P16) -> 142.0537 | Q15: =L15*(1+Q16) -> 131.3725 | R15: =SUM(N15:Q15) -> 698 | S15: =N15*(1+S16) -> 209.52814 | T15: =O15*(1+T16) -> 266.1405 | U15: =P15*(1+U16) -> 159.14899 | V15: =Q15*(1+V16) -> 147.18237 | W15: =SUM(S15:V15) -> 782
A16: YoY | C16: =C15/B15-1 -> -0.30000902 | H16: =H15/C15-1 -> 0.30501662 | I16: 0.5906 | J16: =其他业务!$D$9 -> 0.099250816 | K16: =其他业务!$D$9 -> 0.099250816 | L16: =其他业务!$D$9 -> 0.099250816 | M16: =M15/H15-1 -> 0.19844419 | N16: =其他业务!$E$9 -> 0.14991763 | O16: =其他业务!$E$9 -> 0.14991763 | P16: =其他业务!$E$9 -> 0.14991763 | Q16: =其他业务!$E$9 -> 0.14991763 | R16: =R15/M15-1 -> 0.14991763 | S16: =其他业务!$F$9 -> 0.12034384 | T16: =其他业务!$F$9 -> 0.12034384 | U16: =其他业务!$F$9 -> 0.12034384 | V16: =其他业务!$F$9 -> 0.12034384 | W16: =W15/R15-1 -> 0.12034384
A17: 其中:AI/数据中心(电感+钽电容) | B17: 10 | C17: 50 | D17: 36 | E17: 55 | F17: 86 | G17: 57 | H17: =SUM(D17:G17) -> 234 | I17: 57 | J17: =业务4_AI电感!$C$19 -> 159.75 | K17: =业务4_AI电感!$D$19 -> 217.26 | L17: =业务4_AI电感!$E$19 -> 261.99 | M17: =SUM(I17:L17) -> 696 | N17: =业务4_AI电感!$B$21 -> 296.305 | O17: =业务4_AI电感!$C$21 -> 358.685 | P17: =业务4_AI电感!$D$21 -> 421.065 | Q17: =业务4_AI电感!$E$21 -> 483.445 | R17: =SUM(N17:Q17) -> 1559.5 | S17: =业务4_AI电感!$B$23 -> 524.79 | T17: =业务4_AI电感!$C$23 -> 599.76 | U17: =业务4_AI电感!$D$23 -> 649.74 | V17: =业务4_AI电感!$E$23 -> 724.71 | W17: =SUM(S17:V17) -> 2499
A18: YoY | H18: =H17/C17-1 -> 3.68 | I18: =I17/D17-1 -> 0.58333333 | J18: =J17/E17-1 -> 1.9045455 | K18: =K17/F17-1 -> 1.5262791 | L18: =L17/G17-1 -> 3.5963158 | M18: =M17/H17-1 -> 1.974359 | N18: =N17/I17-1 -> 4.1983333 | O18: =O17/J17-1 -> 1.2452895 | ... W18: =W17/R17-1 -> 0.60243668
A19: 其中:AIoT/物联网端侧 | B19: =B21-B17 -> 342.12 | C19: =C21-C17 -> 338.94 | D19: =D21-D17 -> 109.73 | E19: =E21-E17 -> 125.17 | F19: =F21-F17 -> 144.54 | G19: =G21-G17 -> 119.97 | H19: =H21-H17 -> 499.41 | I19: =D19*(1+I20) -> 134.71552 | J19: =E19*(1+J20) -> 147.7006 | K19: =F19*(1+K20) -> 170.5572 | L19: =G19*(1+L20) -> 141.5646 | M19: =SUM(I19:L19) -> 594.53792 | N19: =I19*(1+N20) -> 158.96431 | O19: =J19*(1+O20) -> 174.28671 | P19: =K19*(1+P20) -> 201.2575 | Q19: =L19*(1+Q20) -> 167.04623 | R19: =SUM(N19:Q19) -> 701.55475 | S19: =N19*(1+S20) -> 182.80896 | T19: =O19*(1+T20) -> 200.42971 | U19: =P19*(1+U20) -> 231.44612 | V19: =Q19*(1+V20) -> 192.10316 | W19: =SUM(S19:V19) -> 806.78796
A20: YoY | H20: =H19/C19-1 -> 0.47344663 | I20: 0.2277 | J20: =业务2_消费AIoT!$D$11 -> 0.18 | K20: =业务2_消费AIoT!$D$11 -> 0.18 | L20: =业务2_消费AIoT!$D$11 -> 0.18 | M20: =M19/H19-1 -> 0.19048061 | N20: =业务2_消费AIoT!$E$11 -> 0.18 | O20: =业务2_消费AIoT!$E$11 -> 0.18 | P20: =业务2_消费AIoT!$E$11 -> 0.18 | Q20: =业务2_消费AIoT!$E$11 -> 0.18 | R20: =R19/M19-1 -> 0.18 | S20: =业务2_消费AIoT!$F$11 -> 0.15 | T20: =业务2_消费AIoT!$F$11 -> 0.15 | U20: =业务2_消费AIoT!$F$11 -> 0.15 | V20: =业务2_消费AIoT!$F$11 -> 0.15 | W20: =W19/R19-1 -> 0.15
A21: 新兴应用合计(AIoT+AI/DC) | B21: 352.12 | C21: 388.94 | D21: 145.73 | E21: 180.17 | F21: 230.54 | G21: 176.97 | H21: 733.41 | I21: =I17+I19 -> 191.71552 | J21: =J17+J19 -> 307.4506 | K21: =K17+K19 -> 387.8172 | L21: =L17+L19 -> 403.5546 | M21: =SUM(I21:L21) -> 1290.5379 | N21: =N17+N19 -> 455.26931 | O21: =O17+O19 -> 532.97171 | P21: =P17+P19 -> 622.3225 | Q21: =Q17+Q19 -> 650.49123 | R21: =SUM(N21:Q21) -> 2261.0547 | S21: =S17+S19 -> 707.59896 | T21: =T17+T19 -> 800.18971 | U21: =U17+U19 -> 881.18612 | V21: =V17+V19 -> 916.81316 | W21: =SUM(S21:V21) -> 3305.788
A22: 同比 YoY | B22: ="" | C22: =C21/B21-1 -> 0.10456663 | D22: ="" | E22: ="" | F22: ="" | G22: ="" | H22: =H21/C21-1 -> 0.8856636 | I22: =I21/D21-1 -> 0.31555288 | J22: =J21/E21-1 -> 0.70644724 | K22: =K21/F21-1 -> 0.6822122 | L22: =L21/G21-1 -> 1.280356 | M22: =M21/H21-1 -> 0.75964048 | N22: =N21/I21-1 -> 1.3747129 | O22: =O21/J21-1 -> 0.73351982 | ... W22: =W21/R21-1 -> 0.46205569
A23: 总收入 | B23: =B7+B9+B11+B13+B15+B21 -> 5040.42 | C23: =C7+C9+C11+C13+C15+C21 -> 5896.91 | D23: =D7+D9+D11+D13+D15+D21 -> 1460.73 | E23: =E7+E9+E11+E13+E15+E21 -> 1763.49 | F23: =F7+F9+F11+F13+F15+F21 -> 1807.81 | G23: =G7+G9+G11+G13+G15+G21 -> 1713.27 | H23: =H7+H9+H11+H13+H15+H21 -> 6745.3 | I23: =I7+I9+I11+I13+I15+I21 -> 1683.9986 | ... L23: =L7+L9+L11+L13+L15+L21 -> 2113.0839 | M23: =SUM(I23:L23) -> 7952.4104 | N23: =N7+N9+N11+N13+N15+N21 -> 2112.9122 | O23: =O7+O9+O11+O13+O15+O21 -> 2441.9587 | P23: =P7+P9+P11+P13+P15+P21 -> 2560.6068 | Q23: =Q7+Q9+Q11+Q13+Q15+Q21 -> 2579.9039 | R23: =SUM(N23:Q23) -> 9695.3816 | S23: =S7+S9+S11+S13+S15+S21 -> 2533.5241 | T23: =T7+T9+T11+T13+T15+T21 -> 2896.0772 | U23: =U7+U9+U11+U13+U15+U21 -> 3028.6677 | V23: =V7+V9+V11+V13+V15+V21 -> 3075.202 | W23: =SUM(S23:V23) -> 11533.471
A24: 同比 YoY | B24: ="" | C24: =C23/B23-1 -> 0.16992433 | D24: ="" | E24: ="" | F24: ="" | G24: ="" | H24: =H23/C23-1 -> 0.14387026 | I24: =I23/D23-1 -> 0.15284728 | J24: =J23/E23-1 -> 0.15220973 | K24: =K23/F23-1 -> 0.17458008 | L24: =L23/G23-1 -> 0.23336302 | M24: =M23/H23-1 -> 0.17895578 | N24: =N23/I23-1 -> 0.25469948 | O24: =O23/J23-1 -> 0.20180438 | ... W24: =W23/R23-1 -> 0.18958402
A25: 勾稽检查: 引擎总收入 − 披露营收 (应≈0) | B25: =B23-5040.4237 -> -0.0037 | C25: =C23-5896.9102 -> -0.0002 | D25: =D23-1460.7352 -> -0.0052 | E25: =E23-1763.4848 -> 0.0052 | F25: =F23-1807.8059 -> 0.0041 | G25: =G23-1713.2656 -> 0.0044 | H25: =H23-6745.2914 -> 0.0086 | I25: =I23-1684 -> -0.001389
A26: 二、分线毛利率 (%) — Q2'26起 ◀绿链行业假设sheet GM路径(QPM 05_Margin_Curve); I列=Q1'26黄底校准至披露32%
A27: 手机通讯 毛利率 | C27: 0.375 | H27: 0.375 | I27: 0.31 | J27: =业务1_手机电感!$B$14 -> 0.345 | K27: =业务1_手机电感!$C$14 -> 0.37 | L27: =业务1_手机电感!$D$14 -> 0.375 | N27: =业务1_手机电感!$E$14 -> 0.385 | O27: =业务1_手机电感!$E$14 -> 0.385 | P27: =业务1_手机电感!$E$14 -> 0.385 | Q27: =业务1_手机电感!$E$14 -> 0.385 | S27: =业务1_手机电感!$F$14 -> 0.388 | T27: =业务1_手机电感!$F$14 -> 0.388 | U27: =业务1_手机电感!$F$14 -> 0.388 | V27: =业务1_手机电感!$F$14 -> 0.388
A28: 消费电子 毛利率 | C28: 0.35 | H28: 0.35 | I28: 0.275 | J28: =业务2_消费AIoT!$B$13 -> 0.315 | K28: =业务2_消费AIoT!$C$13 -> 0.34 | L28: =业务2_消费AIoT!$D$13 -> 0.345 | N28: =业务2_消费AIoT!$E$13 -> 0.355 | O28: =业务2_消费AIoT!$E$13 -> 0.355 | P28: =业务2_消费AIoT!$E$13 -> 0.355 | Q28: =业务2_消费AIoT!$E$13 -> 0.355 | S28: =业务2_消费AIoT!$F$13 -> 0.358 | T28: =业务2_消费AIoT!$F$13 -> 0.358 | U28: =业务2_消费AIoT!$F$13 -> 0.358 | V28: =业务2_消费AIoT!$F$13 -> 0.358
A29: 汽车及储能 毛利率 | C29: 0.38 | H29: 0.37 | I29: 0.345 | J29: =业务3_汽车储能!$B$17 -> 0.35 | K29: =业务3_汽车储能!$C$17 -> 0.355 | L29: =业务3_汽车储能!$D$17 -> 0.355 | N29: =业务3_汽车储能!$E$17 -> 0.355 | O29: =业务3_汽车储能!$E$17 -> 0.355 | P29: =业务3_汽车储能!$E$17 -> 0.355 | Q29: =业务3_汽车储能!$E$17 -> 0.355 | S29: =业务3_汽车储能!$F$17 -> 0.355 | T29: =业务3_汽车储能!$F$17 -> 0.355 | U29: =业务3_汽车储能!$F$17 -> 0.355 | V29: =业务3_汽车储能!$F$17 -> 0.355
A30: 大工业 毛利率 | C30: 0.35 | H30: 0.35 | I30: 0.31 | J30: =其他业务!$B$6 -> 0.33 | K30: =其他业务!$C$6 -> 0.35 | L30: =其他业务!$D$6 -> 0.355 | N30: =其他业务!$E$6 -> 0.355 | O30: =其他业务!$E$6 -> 0.355 | P30: =其他业务!$E$6 -> 0.355 | Q30: =其他业务!$E$6 -> 0.355 | S30: =其他业务!$F$6 -> 0.355 | T30: =其他业务!$F$6 -> 0.355 | U30: =其他业务!$F$6 -> 0.355 | V30: =其他业务!$F$6 -> 0.355
A31: 新兴应用 毛利率 | C31: 0.3433 | H31: 0.3351 | I31: 0.32 | J31: =业务4_AI电感!$B$25 -> 0.34 | K31: =业务4_AI电感!$C$25 -> 0.365 | L31: =业务4_AI电感!$D$25 -> 0.38 | N31: =业务4_AI电感!$E$25 -> 0.41 | O31: =业务4_AI电感!$E$25 -> 0.41 | P31: =业务4_AI电感!$E$25 -> 0.41 | Q31: =业务4_AI电感!$E$25 -> 0.41 | S31: =业务4_AI电感!$F$25 -> 0.42 | T31: =业务4_AI电感!$F$25 -> 0.42 | U31: =业务4_AI电感!$F$25 -> 0.42 | V31: =业务4_AI电感!$F$25 -> 0.42
A32: 特种 毛利率 | C32: 0.45 | H32: 0.45 | I32: 0.42 | J32: =其他业务!$B$10 -> 0.43 | K32: =其他业务!$C$10 -> 0.45 | L32: =其他业务!$D$10 -> 0.46 | N32: =其他业务!$E$10 -> 0.475 | O32: =其他业务!$E$10 -> 0.475 | P32: =其他业务!$E$10 -> 0.475 | Q32: =其他业务!$E$10 -> 0.475 | S32: =其他业务!$F$10 -> 0.48 | T32: =其他业务!$F$10 -> 0.48 | U32: =其他业务!$F$10 -> 0.48 | V32: =其他业务!$F$10 -> 0.48
A33: 分线毛利合计 (引擎) | I33: =I7*I27+I9*I28+I11*I29+I13*I30+I21*I31+I15*I32 -> 541.98189 | J33: =J7*J27+J9*J28+J11*J29+J13*J30+J21*J31+J15*J32 -> 704.12742 | K33: =K7*K27+K9*K28+K11*K29+K13*K30+K21*K31+K15*K32 -> 770.77253 | L33: =L7*L27+L9*L28+L11*L29+L13*L30+L21*L31+L15*L32 -> 779.49781 | M33: =SUM(I33:L33) -> 2796.3796 | N33: =N7*N27+N9*N28+N11*N29+N13*N30+N21*N31+N15*N32 -> 810.45409 | O33: =O7*O27+O9*O28+O11*O29+O13*O30+O21*O31+O15*O32 -> 940.58486 | P33: =P7*P27+P9*P28+P11*P29+P13*P30+P21*P31+P15*P32 -> 976.55842 | Q33: =Q7*Q27+Q9*Q28+Q11*Q29+Q13*Q30+Q21*Q31+Q15*Q32 -> 983.72204 | R33: =SUM(N33:Q33) -> 3711.3194 | S33: =S7*S27+S9*S28+S11*S29+S13*S30+S21*S31+S15*S32 -> 987.16359 | T33: =T7*T27+T9*T28+T11*T29+T13*T30+T21*T31+T15*T32 -> 1132.4053 | U33: =U7*U27+U9*U28+U11*U29+U13*U30+U21*U31+U15*U32 -> 1171.6993 | V33: =V7*V27+V9*V28+V11*V29+V13*V30+V21*V31+V15*V32 -> 1188.9226 | W33: =SUM(S33:V33) -> 4480.1908
A34: 混合毛利率 (实际=IS勾稽 / 预测=引擎) | B34: =IS!B9/IS!B6 -> 0.35348479 | C34: =IS!C9/IS!C6 -> 0.36496081 | D34: =IS!D9/IS!D6 -> 0.36562725 | E34: =IS!E9/IS!E6 -> 0.36781287 | F34: =IS!F9/IS!F6 -> 0.36842855 | G34: =IS!G9/IS!G6 -> 0.36331156 | H34: =IS!H9/IS!H6 -> 0.36636127 | I34: =I33/I23 -> 0.32184224 | J34: =J33/J23 -> 0.34653469 | K34: =K33/K23 -> 0.36298678 | L34: =L33/L23 -> 0.36889109 | M34: =M33/M23 -> 0.35163925 | N34: =N33/N23 -> 0.38357207 | O34: =O33/O23 -> 0.38517639 | P34: =P33/P23 -> 0.38137773 | ... W34: =W33/W23 -> 0.38845121
A35: 三、费用率、其他损益与税 (实际列=由实际值算出的公式;预测=黄底假设)
A36: 税金及附加 占收入% ◀假设 | B36: =-IS!B11/IS!B6 -> 0.014424204 | C36: =-IS!C11/IS!C6 -> 0.013420537 | D36: =-IS!D11/IS!D6 -> 0.012729549 | E36: =-IS!E11/IS!E6 -> 0.011038825 | F36: =-IS!F11/IS!F6 -> 0.011526348 | G36: =-IS!G11/IS!G6 -> 0.011441308 | H36: =-IS!H11/IS!H6 -> 0.011637866 | I36: 0.0115 | J36: 0.0115 | K36: 0.0115 | L36: 0.0115 | N36: 0.0115 | O36: 0.0115 | P36: 0.0115 | Q36: 0.0115 | S36: 0.0115 | T36: 0.0115 | U36: 0.0115 | V36: 0.0115
A37: 销售费用率 ◀假设 | B37: =-IS!B12/IS!B6 -> 0.021104297 | C37: =-IS!C12/IS!C6 -> 0.01748614 | D37: =-IS!D12/IS!D6 -> 0.016778469 | E37: =-IS!E12/IS!E6 -> 0.018339767 | F37: =-IS!F12/IS!F6 -> 0.013342251 | G37: =-IS!G12/IS!G6 -> 0.019663151 | H37: =-IS!H12/IS!H6 -> 0.016998406 | I37: 0.0155 | J37: 0.016 | K37: 0.016 | L37: 0.016 | N37: 0.016 | O37: 0.016 | P37: 0.016 | Q37: 0.016 | S37: 0.016 | T37: 0.016 | U37: 0.016 | V37: 0.016
A38: 管理费用率 ◀假设 | B38: =-IS!B13/IS!B6 -> 0.055882842 | C38: =-IS!C13/IS!C6 -> 0.051538058 | D38: =-IS!D13/IS!D6 -> 0.050535237 | E38: =-IS!E13/IS!E6 -> 0.049446471 | F38: =-IS!F13/IS!F6 -> 0.048178292 | G38: =-IS!G13/IS!G6 -> 0.057581965 | H38: =-IS!H13/IS!H6 -> 0.051408735 | I38: 0.05 | J38: 0.049 | K38: 0.049 | L38: 0.049 | N38: 0.047 | O38: 0.047 | P38: 0.047 | Q38: 0.047 | S38: 0.046 | T38: 0.046 | U38: 0.046 | V38: 0.046
A39: 研发费用率 ◀假设 | B39: =-IS!B14/IS!B6 -> 0.076135822 | C39: =-IS!C14/IS!C6 -> 0.085595826 | D39: =-IS!D14/IS!D6 -> 0.079084833 | E39: =-IS!E14/IS!E6 -> 0.091738585 | F39: =-IS!F14/IS!F6 -> 0.097910401 | G39: =-IS!G14/IS!G6 -> 0.096410854 | H39: =-IS!H14/IS!H6 -> 0.09183919 | I39: 0.102 | J39: 0.093 | K39: 0.093 | L39: 0.093 | N39: 0.089 | O39: 0.089 | P39: 0.089 | Q39: 0.089 | S39: 0.086 | T39: 0.086 | U39: 0.086 | V39: 0.086
A40: 其他收益(政府补助等) ◀假设 | B40: =IS!B16 -> 81.4528 | C40: =IS!C16 -> 103.9494 | D40: =IS!D16 -> 21.4832 | E40: =IS!E16 -> 16.9931 | F40: =IS!F16 -> 18.1189 | G40: =IS!G16 -> 35.622 | H40: =IS!H16 -> 92.2172 | I40: 22 | J40: 25 | K40: 25 | L40: 28 | M40: =SUM(I40:L40) -> 100 | N40: 27 | O40: 27 | P40: 27 | Q40: 27 | R40: =SUM(N40:Q40) -> 108 | S40: 28 | T40: 28 | U40: 28 | V40: 28 | W40: =SUM(S40:V40) -> 112
A41: 投资收益及处置等 ◀假设 | B41: =IS!B17 -> 1.4221 | C41: =IS!C17 -> -5.4835 | D41: =IS!D17 -> 3.1461 | E41: =IS!E17 -> -0.4038 | F41: =IS!F17 -> 1.2452 | G41: =IS!G17 -> 1.9531 | H41: =IS!H17 -> 5.9406 | I41: 2.5 | J41: 2.5 | K41: 2.5 | L41: 2.5 | M41: =SUM(I41:L41) -> 10 | N41: 2.5 | O41: 2.5 | P41: 2.5 | Q41: 2.5 | R41: =SUM(N41:Q41) -> 10 | S41: 2.5 | T41: 2.5 | U41: 2.5 | V41: 2.5 | W41: =SUM(S41:V41) -> 10
...

Sheet IS
A1: 顺络电子 (002138.SZ) — 季度利润表 (Rmb mn)
A2: 收入与毛利由 Drivers 分应用引擎驱动;实际值取自年报/季报(Wind同根双源对账)。
A3: 图例同 Drivers。Q1'26A(I列)为引擎勾稽列:营收/归母/毛利率锚定业绩会披露,费用明细为估算;行39勾稽检查应≈0。
B5: FY2023A | C5: FY2024A | D5: Q1'25A | E5: Q2'25A | F5: Q3'25A | G5: Q4'25A | H5: FY2025A | I5: Q1'26A | J5: Q2'26E | K5: Q3'26E | L5: Q4'26E | M5: FY2026E | N5: Q1'27E | O5: Q2'27E | P5: Q3'27E | Q5: Q4'27E | R5: FY2027E | S5: Q1'28E | T5: Q2'28E | U5: Q3'28E | V5: Q4'28E | W5: FY2028E
A6: 营业收入 | B6: 5040.4237 | C6: 5896.9102 | D6: 1460.7352 | E6: 1763.4848 | F6: 1807.8059 | G6: 1713.2656 | H6: 6745.2914 | I6: =Drivers!I23 -> 1683.9986 | J6: =Drivers!J23 -> 2031.9103 | K6: =Drivers!K23 -> 2123.4176 | L6: =Drivers!L23 -> 2113.0839 | M6: =SUM(I6:L6) -> 7952.4104 | N6: =Drivers!N23 -> 2112.9122 | O6: =Drivers!O23 -> 2441.9587 | P6: =Drivers!P23 -> 2560.6068 | Q6: =Drivers!Q23 -> 2579.9039 | R6: =SUM(N6:Q6) -> 9695.3816 | S6: =Drivers!S23 -> 2533.5241 | T6: =Drivers!T23 -> 2896.0772 | U6: =Drivers!U23 -> 3028.6677 | V6: =Drivers!V23 -> 3075.202 | W6: =SUM(S6:V6) -> 11533.471
A7: 同比 YoY | B7: ="" | C7: =C6/B6-1 -> 0.16992351 | D7: ="" | E7: ="" | F7: ="" | G7: ="" | H7: =H6/C6-1 -> 0.14386877 | I7: =I6/D6-1 -> 0.15284318 | J7: =J6/E6-1 -> 0.15221313 | K7: =K6/F6-1 -> 0.17458274 | L7: =L6/G6-1 -> 0.23336619 | M7: =M6/H6-1 -> 0.17895728 | N7: =N6/I6-1 -> 0.25469948 | O7: =O6/J6-1 -> 0.20180438 | ... W7: =W6/R6-1 -> 0.18958402
A8: 营业成本 | B8: -3258.7106 | C8: -3744.7691 | D8: -926.6506 | E8: -1114.8524 | F8: -1141.7586 | G8: -1090.8164 | H8: -4274.0779 | I8: =-(I6-Drivers!I33) -> -1142.0167 | J8: =-(J6-Drivers!J33) -> -1327.7829 | K8: =-(K6-Drivers!K33) -> -1352.6451 | L8: =-(L6-Drivers!L33) -> -1333.586 | M8: =SUM(I8:L8) -> -5156.0308 | N8: =-(N6-Drivers!N33) -> -1302.4581 | O8: =-(O6-Drivers!O33) -> -1501.3739 | P8: =-(P6-Drivers!P33) -> -1584.0484 | Q8: =-(Q6-Drivers!Q33) -> -1596.1819 | R8: =SUM(N8:Q8) -> -5984.0622 | S8: =-(S6-Drivers!S33) -> -1546.3606 | T8: =-(T6-Drivers!T33) -> -1763.6719 | U8: =-(U6-Drivers!U33) -> -1856.9684 | V8: =-(V6-Drivers!V33) -> -1886.2794 | W8: =SUM(S8:V8) -> -7053.2803
A9: 毛利 | B9: =B6+B8 -> 1781.7131 | C9: =C6+C8 -> 2152.1411 | D9: =D6+D8 -> 534.0846 | E9: =E6+E8 -> 648.6324 | F9: =F6+F8 -> 666.0473 | G9: =G6+G8 -> 622.4492 | H9: =H6+H8 -> 2471.2135 | I9: =I6+I8 -> 541.98189 | ... L9: =L6+L8 -> 779.49781 | M9: =SUM(I9:L9) -> 2796.3796 | N9: =N6+N8 -> 810.45409 | O9: =O6+O8 -> 940.58486 | P9: =P6+P8 -> 976.55842 | Q9: =Q6+Q8 -> 983.72204 | R9: =SUM(N9:Q9) -> 3711.3194 | S9: =S6+S8 -> 987.16359 | T9: =T6+T8 -> 1132.4053 | U9: =U6+U8 -> 1171.6993 | V9: =V6+V8 -> 1188.9226 | W9: =SUM(S9:V9) -> 4480.1908
A10: 毛利率 % | B10: =B9/B6 -> 0.35348479 | C10: =C9/C6 -> 0.36496081 | D10: =D9/D6 -> 0.36562725 | E10: =E9/E6 -> 0.36781287 | F10: =F9/F6 -> 0.36842855 | G10: =G9/G6 -> 0.36331156 | H10: =H9/H6 -> 0.36636127 | I10: =I9/I6 -> 0.32184224 | ... W10: =W9/W6 -> 0.38845121
A11: 税金及附加 | B11: -72.7041 | C11: -79.1397 | D11: -18.5945 | E11: -19.4668 | F11: -20.8374 | G11: -19.602 | H11: -78.5008 | I11: =-I6*Drivers!I36 -> -19.365984 | J11: =-J6*Drivers!J36 -> -23.366969 | K11: =-K6*Drivers!K36 -> -24.419302 | L11: =-L6*Drivers!L36 -> -24.300464 | M11: =SUM(I11:L11) -> -91.45272 | N11: =-N6*Drivers!N36 -> -24.29849 | O11: =-O6*Drivers!O36 -> -28.082526 | P11: =-P6*Drivers!P36 -> -29.446978 | Q11: =-Q6*Drivers!Q36 -> -29.668895 | R11: =SUM(N11:Q11) -> -111.49689 | S11: =-S6*Drivers!S36 -> -29.135528 | T11: =-T6*Drivers!T36 -> -33.304887 | U11: =-U6*Drivers!U36 -> -34.829679 | V11: =-V6*Drivers!V36 -> -35.364823 | W11: =SUM(S11:V11) -> -132.63492
A12: 销售费用 | B12: -106.3746 | C12: -103.1142 | D12: -24.5089 | E12: -32.3419 | F12: -24.1202 | G12: -33.6882 | H12: -114.6592 | I12: =-I6*Drivers!I37 -> -26.101978 | J12: =-J6*Drivers!J37 -> -32.510565 | K12: =-K6*Drivers!K37 -> -33.974682 | L12: =-L6*Drivers!L37 -> -33.809342 | M12: =SUM(I12:L12) -> -126.39657 | N12: =-N6*Drivers!N37 -> -33.806595 | O12: =-O6*Drivers!O37 -> -39.07134 | P12: =-P6*Drivers!P37 -> -40.969709 | Q12: =-Q6*Drivers!Q37 -> -41.278463 | R12: =SUM(N12:Q12) -> -155.12611 | S12: =-S6*Drivers!S37 -> -40.536386 | T12: =-T6*Drivers!T37 -> -46.337235 | U12: =-U6*Drivers!U37 -> -48.458684 | V12: =-V6*Drivers!V37 -> -49.203233 | W12: =SUM(S12:V12) -> -184.53554
A13: 管理费用 | B13: -281.6732 | C13: -303.9153 | D13: -73.8186 | E13: -87.1981 | F13: -87.097 | G13: -98.6532 | H13: -346.7669 | I13: =-I6*Drivers!I38 -> -84.199931 | J13: =-J6*Drivers!J38 -> -99.563607 | K13: =-K6*Drivers!K38 -> -104.04746 | L13: =-L6*Drivers!L38 -> -103.54111 | M13: =SUM(I13:L13) -> -391.35211 | N13: =-N6*Drivers!N38 -> -99.306872 | O13: =-O6*Drivers!O38 -> -114.77206 | P13: =-P6*Drivers!P38 -> -120.34852 | Q13: =-Q6*Drivers!Q38 -> -121.25548 | R13: =SUM(N13:Q13) -> -455.68294 | S13: =-S6*Drivers!S38 -> -116.54211 | T13: =-T6*Drivers!T38 -> -133.21955 | U13: =-U6*Drivers!U38 -> -139.31872 | V13: =-V6*Drivers!V38 -> -141.45929 | W13: =SUM(S13:V13) -> -530.53967
A14: 研发费用 | B14: -383.7568 | C14: -504.7509 | D14: -115.522 | E14: -161.7796 | F14: -177.003 | G14: -165.1774 | H14: -619.4821 | I14: =-I6*Drivers!I39 -> -171.76786 | J14: =-J6*Drivers!J39 -> -188.96766 | K14: =-K6*Drivers!K39 -> -197.47784 | L14: =-L6*Drivers!L39 -> -196.5168 | M14: =SUM(I14:L14) -> -754.73016 | N14: =-N6*Drivers!N39 -> -188.04918 | O14: =-O6*Drivers!O39 -> -217.33433 | P14: =-P6*Drivers!P39 -> -227.89401 | Q14: =-Q6*Drivers!Q39 -> -229.61145 | R14: =SUM(N14:Q14) -> -862.88897 | S14: =-S6*Drivers!S39 -> -217.88308 | T14: =-T6*Drivers!T39 -> -249.06264 | U14: =-U6*Drivers!U39 -> -260.46543 | V14: =-V6*Drivers!V39 -> -264.46738 | W14: =SUM(S14:V14) -> -991.87851
A15: 财务费用 | B15: -73.1935 | C15: -88.3943 | D15: -21.8006 | E15: -17.0879 | F15: -24.4273 | G15: -22.423 | H15: -85.7388 | I15: =-Drivers!I59 -> -22.31866 | J15: =-Drivers!J59 -> -24.52866 | K15: =-Drivers!K59 -> -26.90866 | L15: =-Drivers!L59 -> -28.43866 | M15: =SUM(I15:L15) -> -102.19464 | N15: =-Drivers!N59 -> -29.45866 | O15: =-Drivers!O59 -> -30.81866 | P15: =-Drivers!P59 -> -32.17866 | Q15: =-Drivers!Q59 -> -33.53866 | R15: =SUM(N15:Q15) -> -125.99464 | S15: =-Drivers!S59 -> -34.72866 | T15: =-Drivers!T59 -> -35.74866 | U15: =-Drivers!U59 -> -36.76866 | V15: =-Drivers!V59 -> -37.78866 | W15: =SUM(S15:V15) -> -145.03464
A16: 其他收益 | B16: 81.4528 | C16: 103.9494 | D16: 21.4832 | E16: 16.9931 | F16: 18.1189 | G16: 35.622 | H16: 92.2172 | I16: =Drivers!I40 -> 22 | J16: =Drivers!J40 -> 25 | K16: =Drivers!K40 -> 25 | L16: =Drivers!L40 -> 28 | M16: =SUM(I16:L16) -> 100 | N16: =Drivers!N40 -> 27 | O16: =Drivers!O40 -> 27 | P16: =Drivers!P40 -> 27 | Q16: =Drivers!Q40 -> 27 | R16: =SUM(N16:Q16) -> 108 | S16: =Drivers!S40 -> 28 | T16: =Drivers!T40 -> 28 | U16: =Drivers!U40 -> 28 | V16: =Drivers!V40 -> 28 | W16: =SUM(S16:V16) -> 112
A17: 投资收益/公允/处置净额 | B17: 1.4221 | C17: -5.4835 | D17: 3.1461 | E17: -0.4038 | F17: 1.2452 | G17: 1.9531 | H17: 5.9406 | I17: =Drivers!I41 -> 2.5 | J17: =Drivers!J41 -> 2.5 | K17: =Drivers!K41 -> 2.5 | L17: =Drivers!L41 -> 2.5 | M17: =SUM(I17:L17) -> 10 | N17: =Drivers!N41 -> 2.5 | O17: =Drivers!O41 -> 2.5 | P17: =Drivers!P41 -> 2.5 | Q17: =Drivers!Q41 -> 2.5 | R17: =SUM(N17:Q17) -> 10 | S17: =Drivers!S41 -> 2.5 | T17: =Drivers!T41 -> 2.5 | U17: =Drivers!U41 -> 2.5 | V17: =Drivers!V41 -> 2.5 | W17: =SUM(S17:V17) -> 10
A18: 减值损失(资产+信用) | B18: -102.5097 | C18: -80.2365 | D18: -1.7196 | E18: -0.9472 | F18: -9.8427 | G18: -29.8715 | H18: -42.381 | I18: =Drivers!I42 -> -10.5 | J18: =Drivers!J42 -> -10 | K18: =Drivers!K42 -> -10 | L18: =Drivers!L42 -> -14 | M18: =SUM(I18:L18) -> -44.5 | N18: =Drivers!N42 -> -12 | O18: =Drivers!O42 -> -12 | P18: =Drivers!P42 -> -12 | Q18: =Drivers!Q42 -> -12 | R18: =SUM(N18:Q18) -> -48 | S18: =Drivers!S42 -> -12 | T18: =Drivers!T42 -> -12 | U18: =Drivers!U42 -> -12 | V18: =Drivers!V42 -> -12 | W18: =SUM(S18:V18) -> -48
A19: 营业利润 | B19: =B9+B11+B12+B13+B14+B15+B16+B17+B18 -> 844.3761 | C19: =C9+C11+C12+C13+C14+C15+C16+C17+C18 -> 1091.0561 | D19: =D9+D11+D12+D13+D14+D15+D16+D17+D18 -> 302.7497 | E19: =E9+E11+E12+E13+E14+E15+E16+E17+E18 -> 346.4002 | F19: =F9+F11+F12+F13+F14+F15+F16+F17+F18 -> 342.0838 | G19: =G9+G11+G12+G13+G14+G15+G16+G17+G18 -> 290.609 | H19: =H9+H11+H12+H13+H14+H15+H16+H17+H18 -> 1281.8425 | I19: =I9+I11+I12+I13+I14+I15+I16+I17+I18 -> 232.22748 | ... L19: =L9+L11+L12+L13+L14+L15+L16+L17+L18 -> 409.39144 | M19: =SUM(I19:L19) -> 1395.7535 | N19: =N9+N11+N12+N13+N14+N15+N16+N17+N18 -> 453.03429 | O19: =O9+O11+O12+O13+O14+O15+O16+O17+O18 -> 528.00594 | P19: =P9+P11+P12+P13+P14+P15+P16+P17+P18 -> 543.22054 | Q19: =Q9+Q11+Q12+Q13+Q14+Q15+Q16+Q17+Q18 -> 545.86909 | R19: =SUM(N19:Q19) -> 2070.1299 | S19: =S9+S11+S12+S13+S14+S15+S16+S17+S18 -> 566.83783 | T19: =T9+T11+T12+T13+T14+T15+T16+T17+T18 -> 653.23232 | U19: =U9+U11+U12+U13+U14+U15+U16+U17+U18 -> 670.35813 | V19: =V9+V11+V12+V13+V14+V15+V16+V17+V18 -> 679.13921 | W19: =SUM(S19:V19) -> 2569.5675
A20: 营业利润率 % | B20: =B19/B6 -> 0.16752086 | C20: =C19/C6 -> 0.18502166 | D20: =D19/D6 -> 0.20725844 | E20: =E19/E6 -> 0.19642937 | F20: =F19/F6 -> 0.18922596 | G20: =G19/G6 -> 0.16962285 | H20: =H19/H6 -> 0.19003516 | I20: =I19/I6 -> 0.13790242 | ... W20: =W19/W6 -> 0.22279221
A21: 营业外收支净额 | B21: -4.6157 | C21: -7.8081 | D21: -2.2301 | E21: -2.6528 | F21: -0.7167 | G21: -1.9206 | H21: -7.5202 | I21: =Drivers!I43 -> -2 | J21: =Drivers!J43 -> -2 | K21: =Drivers!K43 -> -2 | L21: =Drivers!L43 -> -2 | M21: =SUM(I21:L21) -> -8 | N21: =Drivers!N43 -> -2 | O21: =Drivers!O43 -> -2 | P21: =Drivers!P43 -> -2 | Q21: =Drivers!Q43 -> -2 | R21: =SUM(N21:Q21) -> -8 | S21: =Drivers!S43 -> -2 | T21: =Drivers!T43 -> -2 | U21: =Drivers!U43 -> -2 | V21: =Drivers!V43 -> -2 | W21: =SUM(S21:V21) -> -8
A22: 利润总额 | B22: =B19+B21 -> 839.7604 | C22: =C19+C21 -> 1083.248 | D22: =D19+D21 -> 300.5196 | E22: =E19+E21 -> 343.7474 | F22: =F19+F21 -> 341.3671 | G22: =G19+G21 -> 288.6884 | H22: =H19+H21 -> 1274.3223 | I22: =I19+I21 -> 230.22748 | ... L22: =L19+L21 -> 407.39144 | M22: =SUM(I22:L22) -> 1387.7535 | N22: =N19+N21 -> 451.03429 | O22: =O19+O21 -> 526.00594 | P22: =P19+P21 -> 541.22054 | Q22: =Q19+Q21 -> 543.86909 | R22: =SUM(N22:Q22) -> 2062.1299 | S22: =S19+S21 -> 564.83783 | T22: =T19+T21 -> 651.23232 | U22: =U19+U21 -> 668.35813 | V22: =V19+V21 -> 677.13921 | W22: =SUM(S22:V22) -> 2561.5675
A23: 所得税 | B23: -99.7314 | C23: -132.9557 | D23: -39.9195 | E23: -45.3684 | F23: -27.0306 | G23: -21.2408 | H23: -133.5593 | I23: =-I22*Drivers!I44 -> -29.929572 | J23: =-J22*Drivers!J44 -> -36.822446 | K23: =-K22*Drivers!K44 -> -41.941681 | L23: =-L22*Drivers!L44 -> -42.776101 | M23: =SUM(I23:L23) -> -151.4698 | N23: =-N22*Drivers!N44 -> -47.358601 | O23: =-O22*Drivers!O44 -> -55.230624 | P23: =-P22*Drivers!P44 -> -56.828157 | Q23: =-Q22*Drivers!Q44 -> -57.106254 | R23: =SUM(N23:Q23) -> -216.52364 | S23: =-S22*Drivers!S44 -> -59.307972 | T23: =-T22*Drivers!T44 -> -68.379393 | U23: =-U22*Drivers!U44 -> -70.177604 | V23: =-V22*Drivers!V44 -> -71.099617 | W23: =SUM(S23:V23) -> -268.96459
A24: 净利润(含少数) | B24: =B22+B23 -> 740.029 | C24: =C22+C23 -> 950.2923 | D24: =D22+D23 -> 260.6001 | E24: =E22+E23 -> 298.379 | F24: =F22+F23 -> 314.3365 | G24: =G22+G23 -> 267.4476 | H24: =H22+H23 -> 1140.763 | I24: =I22+I23 -> 200.2979 | ... L24: =L22+L23 -> 364.61534 | M24: =SUM(I24:L24) -> 1236.2837 | N24: =N22+N23 -> 403.67569 | O24: =O22+O23 -> 470.77532 | P24: =P22+P23 -> 484.39239 | Q24: =Q22+Q23 -> 486.76283 | R24: =SUM(N24:Q24) -> 1845.6062 | S24: =S22+S23 -> 505.52986 | T24: =T22+T23 -> 582.85292 | U24: =U22+U23 -> 598.18053 | V24: =V22+V23 -> 606.03959 | W24: =SUM(S24:V24) -> 2292.6029
A25: 少数股东损益 | B25: -99.4989 | C25: -118.2083 | D25: -27.4492 | E25: -45.6503 | F25: -31.135 | G25: -15.5121 | H25: -119.7467 | I25: =-I24*Drivers!I45 -> -22.03277 | J25: =-J24*Drivers!J45 -> -32.956089 | K25: =-K24*Drivers!K45 -> -37.537804 | L25: =-L24*Drivers!L45 -> -38.28461 | M25: =SUM(I25:L25) -> -130.81127 | N25: =-N24*Drivers!N45 -> -42.385947 | O25: =-O24*Drivers!O45 -> -49.431408 | P25: =-P24*Drivers!P45 -> -50.8612 | Q25: =-Q24*Drivers!Q45 -> -51.110098 | R25: =SUM(N25:Q25) -> -193.78865 | S25: =-S24*Drivers!S45 -> -53.080635 | T25: =-T24*Drivers!T45 -> -61.199557 | U25: =-U24*Drivers!U45 -> -62.808955 | V25: =-V24*Drivers!V45 -> -63.634157 | W25: =SUM(S25:V25) -> -240.7233
A26: 归母净利润 | B26: =B24+B25 -> 640.5301 | C26: =C24+C25 -> 832.084 | D26: =D24+D25 -> 233.1509 | E26: =E24+E25 -> 252.7287 | F26: =F24+F25 -> 283.2015 | G26: =G24+G25 -> 251.9355 | H26: =H24+H25 -> 1021.0163 | I26: =I24+I25 -> 178.26514 | ... L26: =L24+L25 -> 326.33073 | M26: =SUM(I26:L26) -> 1105.4724 | N26: =N24+N25 -> 361.28974 | O26: =O24+O25 -> 421.34391 | P26: =P24+P25 -> 433.53118 | Q26: =Q24+Q25 -> 435.65274 | R26: =SUM(N26:Q26) -> 1651.8176 | S26: =S24+S25 -> 452.44922 | T26: =T24+T25 -> 521.65337 | U26: =U24+U25 -> 535.37157 | V26: =V24+V25 -> 542.40543 | W26: =SUM(S26:V26) -> 2051.8796
A27: 归母净利率 % | B27: =B26/B6 -> 0.12707862 | C27: =C26/C6 -> 0.14110508 | D27: =D26/D6 -> 0.15961202 | E27: =E26/E6 -> 0.14331209 | F27: =F26/F6 -> 0.15665482 | G27: =G26/G6 -> 0.14704988 | H27: =H26/H6 -> 0.15136726 | I27: =I26/I6 -> 0.10585824 | ... W27: =W26/W6 -> 0.17790651
A28: 归母净利 YoY | B28: ="" | C28: =C26/B26-1 -> 0.29905527 | D28: ="" | E28: ="" | F28: ="" | G28: ="" | H28: =H26/C26-1 -> 0.22705917 | I28: =I26/D26-1 -> -0.23540876 | J28: =J26/E26-1 -> 0.11151375 | K28: =K26/F26-1 -> 0.12981427 | L28: =L26/G26-1 -> 0.29529474 | M28: =M26/H26-1 -> 0.082717663 | N28: =N26/I26-1 -> 1.0266988 | O28: =O26/J26-1 -> 0.49991731 | ... W28: =W26/R26-1 -> 0.24219504
A29: EPS (元) | B29: =B26/B36 -> 0.79438854 | C29: =C26/C36 -> 1.0319546 | D29: =D26/D36 -> 0.28915488 | E29: =E26/E36 -> 0.31343536 | F29: =F26/F36 -> 0.35122788 | G29: =G26/G36 -> 0.31245163 | H29: =H26/H36 -> 1.2662694 | I29: =I26/I36 -> 0.22108529 | ... W29: =W26/W36 -> 2.5447511
A30: Memo(备查):
A31: 扣非归母净利润 (披露) | B31: 591.9201 | C31: 781.1132 | D31: 186.1206 | E31: 242.11 | F31: 270.83 | G31: 245.07 | H31: 978.2092 | I31: 167
A32: D&A | B32: =Drivers!B49 -> 542.5572 | C32: =Drivers!C49 -> 595.8623 | D32: =Drivers!D49 -> 153.94585 | E32: =Drivers!E49 -> 153.94585 | F32: =Drivers!F49 -> 153.94585 | G32: =Drivers!G49 -> 153.94585 | H32: =Drivers!H49 -> 615.7834 | I32: =Drivers!I49 -> 164.7 | ... L32: =Drivers!L49 -> 173.7 | M32: =SUM(I32:L32) -> 676.8 | N32: =Drivers!N49 -> 182.7 | O32: =Drivers!O49 -> 185.7 | P32: =Drivers!P49 -> 188.7 | Q32: =Drivers!Q49 -> 191.7 | R32: =SUM(N32:Q32) -> 748.8 | S32: =Drivers!S49 -> 202.7 | T32: =Drivers!T49 -> 205.7 | U32: =Drivers!U49 -> 208.7 | V32: =Drivers!V49 -> 211.7 | W32: =SUM(S32:V32) -> 828.8
A33: EBIT (=营业利润+财务费用) | B33: =B19-B15 -> 917.5696 | C33: =C19-C15 -> 1179.4504 | D33: =D19-D15 -> 324.5503 | E33: =E19-E15 -> 363.4881 | F33: =F19-F15 -> 366.5111 | G33: =G19-G15 -> 313.032 | H33: =H19-H15 -> 1367.5813 | I33: =I19-I15 -> 254.54614 | ... L33: =L19-L15 -> 437.8301 | M33: =SUM(I33:L33) -> 1497.9481 | N33: =N19-N15 -> 482.49295 | O33: =O19-O15 -> 558.8246 | P33: =P19-P15 -> 575.3992 | Q33: =Q19-Q15 -> 579.40775 | R33: =SUM(N33:Q33) -> 2196.1245 | S33: =S19-S15 -> 601.56649 | T33: =T19-T15 -> 688.98098 | U33: =U19-U15 -> 707.12679 | V33: =V19-V15 -> 716.92787 | W33: =SUM(S33:V33) -> 2714.6021
A34: EBITDA (=EBIT+D&A) | B34: =B33+B32 -> 1460.1268 | C34: =C33+C32 -> 1775.3127 | D34: =D33+D32 -> 478.49615 | E34: =E33+E32 -> 517.43395 | F34: =F33+F32 -> 520.45695 | G34: =G33+G32 -> 466.97785 | H34: =H33+H32 -> 1983.3647 | I34: =I33+I32 -> 419.24614 | ... L34: =L33+L32 -> 611.5301 | M34: =SUM(I34:L34) -> 2174.7481 | N34: =N33+N32 -> 665.19295 | O34: =O33+O32 -> 744.5246 | P34: =P33+P32 -> 764.0992 | Q34: =Q33+Q32 -> 771.10775 | R34: =SUM(N34:Q34) -> 2944.9245 | S34: =S33+S32 -> 804.26649 | T34: =T33+T32 -> 894.68098 | U34: =U33+U32 -> 915.82679 | V34: =V33+V32 -> 928.62787 | W34: =SUM(S34:V34) -> 3543.4021
A35: EBITDA 利润率 % | B35: =B34/B6 -> 0.28968335 | C35: =C34/C6 -> 0.30105812 | D35: =D34/D6 -> 0.32757214 | E35: =E34/E6 -> 0.2934156 | F35: =F34/F6 -> 0.28789426 | G35: =G34/G6 -> 0.27256594 | H35: =H34/H6 -> 0.29403692 | I35: =I34/I6 -> 0.24895872 | ... W35: =W34/W6 -> 0.30722773
A36: 总股本 (百万股) | B36: =Drivers!B61 -> 806.3184 | C36: =Drivers!C61 -> 806.3184 | D36: =Drivers!D61 -> 806.3184 | E36: =Drivers!E61 -> 806.3184 | F36: =Drivers!F61 -> 806.3184 | G36: =Drivers!G61 -> 806.3184 | H36: =Drivers!H61 -> 806.3184 | I36: =Drivers!I61 -> 806.3184 | ... W36: =Drivers!W61 -> 806.3184
A38: 披露锚: Q1'26归母净利(业绩会) | I38: 178
A39: 勾稽检查: 模型归母 − 披露锚 (应≈0) | I39: =I26-I38 -> 0.26513516

Sheet BS
A1: 顺络电子 (002138.SZ) — 资产负债表 (Rmb mn)
A2: 营运资本由 Drivers DSO/DIO/DPO 驱动(季度91.25天);现金链接CF;固定资产=滚动(+Capex−折旧)。
A3: 图例同 Drivers。实际列仅FY23/24/25(年报);2025季度与Q1'26无披露BS→Q1'26起由FY25滚动推算;行32平衡检查必须=0。
B5: FY2023A | C5: FY2024A | D5: Q1'25A | E5: Q2'25A | F5: Q3'25A | G5: Q4'25A | H5: FY2025A | I5: Q1'26A | J5: Q2'26E | K5: Q3'26E | L5: Q4'26E | M5: FY2026E | N5: Q1'27E | O5: Q2'27E | P5: Q3'27E | Q5: Q4'27E | R5: FY2027E | S5: Q1'28E | T5: Q2'28E | U5: Q3'28E | V5: Q4'28E | W5: FY2028E
A6: 资产
A7: 货币资金 | B7: 778.838 | C7: 302.2738 | H7: 349.9729 | I7: =CF!I31 -> 686.95305 | J7: =CF!J31 -> 419.13852 | K7: =CF!K31 -> 23.335613 | L7: =CF!L31 -> 295.98616 | M7: =L7 -> 295.98616 | N7: =CF!N31 -> 771.55621 | O7: =CF!O31 -> 602.59943 | P7: =CF!P31 -> 169.53745 | Q7: =CF!Q31 -> 682.98831 | R7: =Q7 -> 682.98831 | S7: =CF!S31 -> 1370.7225 | T7: =CF!T31 -> 1260.5486 | U7: =CF!U31 -> 596.01495 | V7: =CF!V31 -> 1182.9539 | W7: =V7 -> 1182.9539
A8: 应收款项(票据+账款+应收款项融资) | B8: 2706.2244 | C8: 3060.2289 | H8: 3312.8074 | I8: =Drivers!I51*IS!I6/91.25 -> 3284.9507 | J8: =Drivers!J51*IS!J6/91.25 -> 3963.6169 | K8: =Drivers!K51*IS!K6/91.25 -> 4142.1187 | L8: =Drivers!L51*IS!L6/91.25 -> 4121.9608 | M8: =L8 -> 4121.9608 | N8: =Drivers!N51*IS!N6/91.25 -> 4075.3155 | O8: =Drivers!O51*IS!O6/91.25 -> 4709.9698 | P8: =Drivers!P51*IS!P6/91.25 -> 4938.8142 | Q8: =Drivers!Q51*IS!Q6/91.25 -> 4976.0338 | R8: =Q8 -> 4976.0338 | S8: =Drivers!S51*IS!S6/91.25 -> 4831.0488 | T8: =Drivers!T51*IS!T6/91.25 -> 5522.3828 | U8: =Drivers!U51*IS!U6/91.25 -> 5775.213 | V8: =Drivers!V51*IS!V6/91.25 -> 5863.9469 | W8: =V8 -> 5863.9469
A9: 存货 | B9: 864.6083 | C9: 997.0448 | H9: 1321.581 | I9: =-Drivers!I52*IS!I8/91.25 -> 1439.254 | J9: =-Drivers!J52*IS!J8/91.25 -> 1673.3703 | K9: =-Drivers!K52*IS!K8/91.25 -> 1704.7034 | L9: =-Drivers!L52*IS!L8/91.25 -> 1680.6838 | M9: =L9 -> 1680.6838 | N9: =-Drivers!N52*IS!N8/91.25 -> 1655.7275 | O9: =-Drivers!O52*IS!O8/91.25 -> 1908.5959 | P9: =-Drivers!P52*IS!P8/91.25 -> 2013.6944 | Q9: =-Drivers!Q52*IS!Q8/91.25 -> 2029.1189 | R9: =Q9 -> 2029.1189 | S9: =-Drivers!S52*IS!S8/91.25 -> 1982.7308 | T9: =-Drivers!T52*IS!T8/91.25 -> 2261.3656 | U9: =-Drivers!U52*IS!U8/91.25 -> 2380.9897 | V9: =-Drivers!V52*IS!V8/91.25 -> 2418.572 | W9: =V9 -> 2418.572
A10: 预付/其他应收/其他流动资产 | B10: 295.4011 | C10: 340.2844 | H10: 289.4369 | I10: =H10 -> 289.4369 | J10: =I10 -> 289.4369 | K10: =J10 -> 289.4369 | L10: =K10 -> 289.4369 | M10: =L10 -> 289.4369 | N10: =L10 -> 289.4369 | O10: =N10 -> 289.4369 | P10: =O10 -> 289.4369 | Q10: =P10 -> 289.4369 | R10: =Q10 -> 289.4369 | S10: =Q10 -> 289.4369 | T10: =S10 -> 289.4369 | U10: =T10 -> 289.4369 | V10: =U10 -> 289.4369 | W10: =V10 -> 289.4369
A11: 流动资产合计 | B11: =SUM(B7:B10) -> 4645.0718 | C11: =SUM(C7:C10) -> 4699.8319 | H11: =SUM(H7:H10) -> 5273.7982 | I11: =SUM(I7:I10) -> 5700.5946 | J11: =SUM(J7:J10) -> 6345.5626 | K11: =SUM(K7:K10) -> 6159.5946 | L11: =SUM(L7:L10) -> 6388.0677 | M11: =SUM(M7:M10) -> 6388.0677 | N11: =SUM(N7:N10) -> 6792.0362 | O11: =SUM(O7:O10) -> 7510.6019 | ... W11: =SUM(W7:W10) -> 9754.9097
A12: 固定资产及在建工程 | B12: 6539.0618 | C12: 6655.1886 | H12: 6779.9748 | I12: =H12+Drivers!I50-Drivers!I47 -> 6961.9748 | J12: =I12+Drivers!J50-Drivers!J47 -> 7180.9748 | K12: =J12+Drivers!K50-Drivers!K47 -> 7406.9748 | L12: =K12+Drivers!L50-Drivers!L47 -> 7629.9748 | M12: =L12 -> 7629.9748 | N12: =L12+Drivers!N50-Drivers!N47 -> 7803.9748 | O12: =N12+Drivers!O50-Drivers!O47 -> 7969.9748 | P12: =O12+Drivers!P50-Drivers!P47 -> 8127.9748 | Q12: =P12+Drivers!Q50-Drivers!Q47 -> 8267.9748 | R12: =Q12 -> 8267.9748 | S12: =Q12+Drivers!S50-Drivers!S47 -> 8381.9748 | T12: =S12+Drivers!T50-Drivers!T47 -> 8487.9748 | U12: =T12+Drivers!U50-Drivers!U47 -> 8585.9748 | V12: =U12+Drivers!V50-Drivers!V47 -> 8665.9748 | W12: =V12 -> 8665.9748
A13: 无形资产 | B13: 510.5883 | C13: 497.1866 | H13: 485.015 | I13: =H13-Drivers!I48 -> 478.315 | J13: =I13-Drivers!J48 -> 471.615 | K13: =J13-Drivers!K48 -> 464.915 | L13: =K13-Drivers!L48 -> 458.215 | M13: =L13 -> 458.215 | N13: =L13-Drivers!N48 -> 451.515 | O13: =N13-Drivers!O48 -> 444.815 | P13: =O13-Drivers!P48 -> 438.115 | Q13: =P13-Drivers!Q48 -> 431.415 | R13: =Q13 -> 431.415 | S13: =Q13-Drivers!S48 -> 424.715 | T13: =S13-Drivers!T48 -> 418.015 | U13: =T13-Drivers!U48 -> 411.315 | V13: =U13-Drivers!V48 -> 404.615 | W13: =V13 -> 404.615
A14: 商誉 | B14: 340.5146 | C14: 301.8712 | H14: 301.8712 | I14: =H14 -> 301.8712 | J14: =I14 -> 301.8712 | K14: =J14 -> 301.8712 | L14: =K14 -> 301.8712 | M14: =L14 -> 301.8712 | N14: =L14 -> 301.8712 | O14: =N14 -> 301.8712 | P14: =O14 -> 301.8712 | Q14: =P14 -> 301.8712 | R14: =Q14 -> 301.8712 | S14: =Q14 -> 301.8712 | T14: =S14 -> 301.8712 | U14: =T14 -> 301.8712 | V14: =U14 -> 301.8712 | W14: =V14 -> 301.8712
A15: 其他非流动资产(长期股权/递延税等) | B15: 533.1558 | C15: 551.9984 | H15: 452.8503 | I15: =H15 -> 452.8503 | J15: =I15 -> 452.8503 | K15: =J15 -> 452.8503 | L15: =K15 -> 452.8503 | M15: =L15 -> 452.8503 | N15: =L15 -> 452.8503 | O15: =N15 -> 452.8503 | P15: =O15 -> 452.8503 | Q15: =P15 -> 452.8503 | R15: =Q15 -> 452.8503 | S15: =Q15 -> 452.8503 | T15: =S15 -> 452.8503 | U15: =T15 -> 452.8503 | V15: =U15 -> 452.8503 | W15: =V15 -> 452.8503
A16: 非流动资产合计 | B16: =SUM(B12:B15) -> 7923.3205 | C16: =SUM(C12:C15) -> 8006.2448 | H16: =SUM(H12:H15) -> 8019.7113 | I16: =SUM(I12:I15) -> 8195.0113 | J16: =SUM(J12:J15) -> 8407.3113 | K16: =SUM(K12:K15) -> 8626.6113 | L16: =SUM(L12:L15) -> 8842.9113 | M16: =SUM(M12:M15) -> 8842.9113 | N16: =SUM(N12:N15) -> 9010.2113 | O16: =SUM(O12:O15) -> 9169.5113 | ... W16: =SUM(W12:W15) -> 9825.3113
A17: 资产总计 | B17: =B11+B16 -> 12568.392 | C17: =C11+C16 -> 12706.077 | H17: =H11+H16 -> 13293.51 | I17: =I11+I16 -> 13895.606 | J17: =J11+J16 -> 14752.874 | K17: =K11+K16 -> 14786.206 | L17: =L11+L16 -> 15230.979 | M17: =M11+M16 -> 15230.979 | N17: =N11+N16 -> 15802.247 | O17: =O11+O16 -> 16680.113 | ... W17: =W11+W16 -> 19580.221
A19: 负债与权益
A20: 短期借款及一年内到期(=借款引擎−长借) | B20: 1629.65 | C20: 1242.2235 | H20: 1041.3129 | I20: =Drivers!I57-I25 -> 1341.3129 | J20: =Drivers!J57-J25 -> 1691.3129 | K20: =Drivers!K57-K25 -> 2041.3129 | L20: =Drivers!L57-L25 -> 2141.3129 | M20: =L20 -> 2141.3129 | N20: =Drivers!N57-N25 -> 2341.3129 | O20: =Drivers!O57-O25 -> 2541.3129 | P20: =Drivers!P57-P25 -> 2741.3129 | Q20: =Drivers!Q57-Q25 -> 2941.3129 | R20: =Q20 -> 2941.3129 | S20: =Drivers!S57-S25 -> 3091.3129 | T20: =Drivers!T57-T25 -> 3241.3129 | U20: =Drivers!U57-U25 -> 3391.3129 | V20: =Drivers!V57-V25 -> 3541.3129 | W20: =V20 -> 3541.3129
A21: 应付票据及应付账款 | B21: 803.4902 | C21: 900.2462 | H21: 1087.1498 | I21: =-Drivers!I53*IS!I8/91.25 -> 1188.9489 | J21: =-Drivers!J53*IS!J8/91.25 -> 1382.3493 | K21: =-Drivers!K53*IS!K8/91.25 -> 1408.2332 | L21: =-Drivers!L53*IS!L8/91.25 -> 1388.391 | M21: =L21 -> 1388.391 | N21: =-Drivers!N53*IS!N8/91.25 -> 1355.9838 | O21: =-Drivers!O53*IS!O8/91.25 -> 1563.0742 | P21: =-Drivers!P53*IS!P8/91.25 -> 1649.1463 | Q21: =-Drivers!Q53*IS!Q8/91.25 -> 1661.7784 | R21: =Q21 -> 1661.7784 | S21: =-Drivers!S53*IS!S8/91.25 -> 1609.9096 | T21: =-Drivers!T53*IS!T8/91.25 -> 1836.1516 | U21: =-Drivers!U53*IS!U8/91.25 -> 1933.2822 | V21: =-Drivers!V53*IS!V8/91.25 -> 1963.7978 | W21: =V21 -> 1963.7978
A22: 合同负债 | B22: 10.3965 | C22: 16.472 | H22: 11.3676 | I22: =H22 -> 11.3676 | J22: =I22 -> 11.3676 | K22: =J22 -> 11.3676 | L22: =K22 -> 11.3676 | M22: =L22 -> 11.3676 | N22: =L22 -> 11.3676 | O22: =N22 -> 11.3676 | P22: =O22 -> 11.3676 | Q22: =P22 -> 11.3676 | R22: =Q22 -> 11.3676 | S22: =Q22 -> 11.3676 | T22: =S22 -> 11.3676 | U22: =T22 -> 11.3676 | V22: =U22 -> 11.3676 | W22: =V22 -> 11.3676
A23: 其他流动负债(薪酬/税费/其他应付) | B23: 955.0742 | C23: 1055.372 | H23: 1255.6982 | I23: =H23 -> 1255.6982 | J23: =I23 -> 1255.6982 | K23: =J23 -> 1255.6982 | L23: =K23 -> 1255.6982 | M23: =L23 -> 1255.6982 | N23: =L23 -> 1255.6982 | O23: =N23 -> 1255.6982 | P23: =O23 -> 1255.6982 | Q23: =P23 -> 1255.6982 | R23: =Q23 -> 1255.6982 | S23: =Q23 -> 1255.6982 | T23: =S23 -> 1255.6982 | U23: =T23 -> 1255.6982 | V23: =U23 -> 1255.6982 | W23: =V23 -> 1255.6982
A24: 流动负债合计 | B24: =SUM(B20:B23) -> 3398.6109 | C24: =SUM(C20:C23) -> 3214.3137 | H24: =SUM(H20:H23) -> 3395.5285 | I24: =SUM(I20:I23) -> 3797.3276 | J24: =SUM(J20:J23) -> 4340.728 | K24: =SUM(K20:K23) -> 4716.6119 | L24: =SUM(L20:L23) -> 4796.7697 | M24: =SUM(M20:M23) -> 4796.7697 | N24: =SUM(N20:N23) -> 4964.3625 | O24: =SUM(O20:O23) -> 5371.4529 | ... W24: =SUM(W20:W23) -> 6772.1765
A25: 长期借款 | B25: 2115.9252 | C25: 2039.2276 | H25: 2090.843 | I25: =H25 -> 2090.843 | J25: =I25 -> 2090.843 | K25: =J25 -> 2090.843 | L25: =K25 -> 2090.843 | M25: =L25 -> 2090.843 | N25: =L25 -> 2090.843 | O25: =N25 -> 2090.843 | P25: =O25 -> 2090.843 | Q25: =P25 -> 2090.843 | R25: =Q25 -> 2090.843 | S25: =Q25 -> 2090.843 | T25: =S25 -> 2090.843 | U25: =T25 -> 2090.843 | V25: =U25 -> 2090.843 | W25: =V25 -> 2090.843
A26: 其他非流动负债(递延税/递延收益) | B26: 514.2447 | C26: 499.5884 | H26: 384.0323 | I26: =H26 -> 384.0323 | J26: =I26 -> 384.0323 | K26: =J26 -> 384.0323 | L26: =K26 -> 384.0323 | M26: =L26 -> 384.0323 | N26: =L26 -> 384.0323 | O26: =N26 -> 384.0323 | P26: =O26 -> 384.0323 | Q26: =P26 -> 384.0323 | R26: =Q26 -> 384.0323 | S26: =Q26 -> 384.0323 | T26: =S26 -> 384.0323 | U26: =T26 -> 384.0323 | V26: =U26 -> 384.0323 | W26: =V26 -> 384.0323
A27: 负债合计 | B27: =B24+B25+B26 -> 6028.7808 | C27: =C24+C25+C26 -> 5753.1297 | H27: =H24+H25+H26 -> 5870.4038 | I27: =I24+I25+I26 -> 6272.2029 | J27: =J24+J25+J26 -> 6815.6033 | K27: =K24+K25+K26 -> 7191.4872 | L27: =L24+L25+L26 -> 7271.645 | M27: =M24+M25+M26 -> 7271.645 | N27: =N24+N25+N26 -> 7439.2378 | O27: =O24+O25+O26 -> 7846.3282 | ... W27: =W24+W25+W26 -> 9247.0518
A28: 少数股东权益 | B28: 575.9152 | C28: 690.1829 | H28: 643.3698 | I28: =H28-IS!I25+CF!I24 -> 665.40257 | J28: =I28-IS!J25+CF!J24 -> 698.35866 | K28: =J28-IS!K25+CF!K24 -> 680.89646 | L28: =K28-IS!L25+CF!L24 -> 719.18107 | M28: =L28 -> 719.18107 | N28: =L28-IS!N25+CF!N24 -> 761.56702 | O28: =N28-IS!O25+CF!O24 -> 810.99843 | P28: =O28-IS!P25+CF!P24 -> 806.85963 | Q28: =P28-IS!Q25+CF!Q24 -> 857.96973 | R28: =Q28 -> 857.96973 | S28: =Q28-IS!S25+CF!S24 -> 911.05036 | T28: =S28-IS!T25+CF!T24 -> 972.24992 | U28: =T28-IS!U25+CF!U24 -> 980.05887 | V28: =U28-IS!V25+CF!V24 -> 1043.693 | W28: =V28 -> 1043.693
A29: 归属母公司股东权益 | B29: 5963.6963 | C29: 6262.7641 | H29: 6779.7356 | I29: =H29+IS!I26+CF!I23 -> 6958.0007 | J29: =I29+IS!J26+CF!J23 -> 7238.9122 | K29: =J29+IS!K26+CF!K23 -> 6913.8225 | L29: =K29+IS!L26+CF!L23 -> 7240.1533 | M29: =L29 -> 7240.1533 | N29: =L29+IS!N26+CF!N23 -> 7601.443 | O29: =N29+IS!O26+CF!O23 -> 8022.7869 | P29: =O29+IS!P26+CF!P23 -> 7793.0347 | Q29: =P29+IS!Q26+CF!Q23 -> 8228.6874 | R29: =Q29 -> 8228.6874 | S29: =Q29+IS!S26+CF!S23 -> 8681.1366 | T29: =S29+IS!T26+CF!T23 -> 9202.79 | U29: =T29+IS!U26+CF!U23 -> 8747.071 | V29: =U29+IS!V26+CF!V23 -> 9289.4765 | W29: =V29 -> 9289.4765
A30: 股东权益合计 | B30: =B28+B29 -> 6539.6115 | C30: =C28+C29 -> 6952.947 | H30: =H28+H29 -> 7423.1054 | I30: =I28+I29 -> 7623.4033 | J30: =J28+J29 -> 7937.2708 | K30: =K28+K29 -> 7594.719 | L30: =L28+L29 -> 7959.3343 | M30: =M28+M29 -> 7959.3343 | N30: =N28+N29 -> 8363.01 | O30: =O28+O29 -> 8833.7853 | ... W30: =W28+W29 -> 10333.169
A31: 负债与股东权益总计 | B31: =B27+B30 -> 12568.392 | C31: =C27+C30 -> 12706.077 | H31: =H27+H30 -> 13293.509 | I31: =I27+I30 -> 13895.606 | J31: =J27+J30 -> 14752.874 | K31: =K27+K30 -> 14786.206 | L31: =L27+L30 -> 15230.979 | M31: =M27+M30 -> 15230.979 | N31: =N27+N30 -> 15802.248 | O31: =O27+O30 -> 16680.114 | ... W31: =W27+W30 -> 19580.221
A32: 平衡检查 (资产−负债权益, 必须=0) | B32: =B17-B31 -> 0 | C32: =C17-C31 -> 0 | H32: =H17-H31 -> 0.0003 | I32: =I17-I31 -> -0.0003 | J32: =J17-J31 -> -0.0003 | K32: =K17-K31 -> -0.0003 | L32: =L17-L31 -> -0.0003 | M32: =M17-M31 -> -0.0003 | N32: =N17-N31 -> -0.0003 | O32: =O17-O31 -> -0.0003 | ... W32: =W17-W31 -> -0.0003
A34: 净债务(借款合计−货币资金) | B34: =B20+B25-B7 -> 2966.7372 | C34: =C20+C25-C7 -> 2979.1773 | H34: =H20+H25-H7 -> 2782.183 | I34: =I20+I25-I7 -> 2745.2028 | J34: =J20+J25-J7 -> 3363.0174 | K34: =K20+K25-K7 -> 4108.8203 | L34: =L20+L25-L7 -> 3936.1697 | M34: =M20+M25-M7 -> 3936.1697 | N34: =N20+N25-N7 -> 3660.5997 | O34: =O20+O25-O7 -> 4029.5565 | ... W34: =W20+W25-W7 -> 4449.202
A35: 净债务/EBITDA (x, 年度) | B35: =B34/IS!B34 -> 2.0318353 | C35: =C34/IS!C34 -> 1.6781141 | H35: =H34/IS!H34 -> 1.4027592 | M35: =M34/IS!M34 -> 1.8099428 | R35: =R34/IS!R34 -> 1.476835 | W35: =W34/IS!W34 -> 1.25563

Sheet CF
A1: 顺络电子 (002138.SZ) — 现金流量表 (Rmb mn)
A2: 预测期营运资本变动取自BS期间差额,期末现金回链BS;实际列为Wind年报口径(利息列于筹资)。
A3: 图例同 Drivers。注:预测期口径=净利润起步(利息已含于净利),故筹资段不再单列利息;减值在预测期不加回(资产由天数驱动)。
B5: FY2023A | C5: FY2024A | D5: Q1'25A | E5: Q2'25A | F5: Q3'25A | G5: Q4'25A | H5: FY2025A | I5: Q1'26A | J5: Q2'26E | K5: Q3'26E | L5: Q4'26E | M5: FY2026E | N5: Q1'27E | O5: Q2'27E | P5: Q3'27E | Q5: Q4'27E | R5: FY2027E | S5: Q1'28E | T5: Q2'28E | U5: Q3'28E | V5: Q4'28E | W5: FY2028E
A6: 经营活动
A7: 净利润(含少数) | B7: 740.0288 | C7: 950.2925 | H7: 1140.763 | I7: =IS!I24 -> 200.2979 | J7: =IS!J24 -> 313.86751 | K7: =IS!K24 -> 357.5029 | L7: =IS!L24 -> 364.61534 | M7: =SUM(I7:L7) -> 1236.2837 | N7: =IS!N24 -> 403.67569 | O7: =IS!O24 -> 470.77532 | P7: =IS!P24 -> 484.39239 | Q7: =IS!Q24 -> 486.76283 | R7: =SUM(N7:Q7) -> 1845.6062 | S7: =IS!S24 -> 505.52986 | T7: =IS!T24 -> 582.85292 | U7: =IS!U24 -> 598.18053 | V7: =IS!V24 -> 606.03959 | W7: =SUM(S7:V7) -> 2292.6029
A8: (+) D&A | B8: 542.5572 | C8: 595.8622 | H8: 615.7832 | I8: =Drivers!I49 -> 164.7 | J8: =Drivers!J49 -> 167.7 | K8: =Drivers!K49 -> 170.7 | L8: =Drivers!L49 -> 173.7 | M8: =SUM(I8:L8) -> 676.8 | N8: =Drivers!N49 -> 182.7 | O8: =Drivers!O49 -> 185.7 | P8: =Drivers!P49 -> 188.7 | Q8: =Drivers!Q49 -> 191.7 | R8: =SUM(N8:Q8) -> 748.8 | S8: =Drivers!S49 -> 202.7 | T8: =Drivers!T49 -> 205.7 | U8: =Drivers!U49 -> 208.7 | V8: =Drivers!V49 -> 211.7 | W8: =SUM(S8:V8) -> 828.8
A9: (+) 减值准备(实际列) | B9: 85.5399 | C9: 65.1643 | H9: 37.8568 | M9: =SUM(I9:L9) -> 0 | R9: =SUM(N9:Q9) -> 0 | W9: =SUM(S9:V9) -> 0
A10: (−) Δ应收款项 | I10: =-(BS!I8-BS!H8) -> 27.856685 | J10: =-(BS!J8-BS!I8) -> -678.66617 | K10: =-(BS!K8-BS!J8) -> -178.50184 | L10: =-(BS!L8-BS!K8) -> 20.157883 | M10: =SUM(I10:L10) -> -809.15345 | N10: =-(BS!N8-BS!L8) -> 46.645305 | O10: =-(BS!O8-BS!N8) -> -634.65421 | P10: =-(BS!P8-BS!O8) -> -228.84447 | Q10: =-(BS!Q8-BS!P8) -> -37.219614 | R10: =SUM(N10:Q10) -> -854.07299 | S10: =-(BS!S8-BS!Q8) -> 144.98506 | T10: =-(BS!T8-BS!S8) -> -691.33399 | U10: =-(BS!U8-BS!T8) -> -252.83022 | V10: =-(BS!V8-BS!U8) -> -88.733911 | W10: =SUM(S10:V10) -> -887.91306
A11: (−) Δ存货 | I11: =-(BS!I9-BS!H9) -> -117.67295 | J11: =-(BS!J9-BS!I9) -> -234.1163 | K11: =-(BS!K9-BS!J9) -> -31.333138 | L11: =-(BS!L9-BS!K9) -> 24.019605 | M11: =SUM(I11:L11) -> -359.10279 | N11: =-(BS!N9-BS!L9) -> 24.956247 | O11: =-(BS!O9-BS!N9) -> -252.86831 | P11: =-(BS!P9-BS!O9) -> -105.09854 | Q11: =-(BS!Q9-BS!P9) -> -15.424477 | R11: =SUM(N11:Q11) -> -348.43508 | S11: =-(BS!S9-BS!Q9) -> 46.388083 | T11: =-(BS!T9-BS!S9) -> -278.63481 | U11: =-(BS!U9-BS!T9) -> -119.62408 | V11: =-(BS!V9-BS!U9) -> -37.582331 | W11: =SUM(S11:V11) -> -389.45313
A12: (+) Δ应付款项 | I12: =(BS!I21-BS!H21) -> 101.79912 | J12: =(BS!J21-BS!I21) -> 193.40042 | K12: =(BS!K21-BS!J21) -> 25.883896 | L12: =(BS!L21-BS!K21) -> -19.842283 | M12: =SUM(I12:L12) -> 301.24115 | N12: =(BS!N21-BS!L21) -> -32.407193 | O12: =(BS!O21-BS!N21) -> 207.09043 | P12: =(BS!P21-BS!O21) -> 86.072081 | Q12: =(BS!Q21-BS!P21) -> 12.632115 | R12: =SUM(N12:Q12) -> 273.38743 | S12: =(BS!S21-BS!Q21) -> -51.868772 | T12: =(BS!T21-BS!S21) -> 226.24194 | U12: =(BS!U21-BS!T21) -> 97.130661 | V12: =(BS!V21-BS!U21) -> 30.515568 | W12: =SUM(S12:V12) -> 302.01939
A13: (+/−) 其他经营调整(实际=勾稽) | B13: =B14-B7-B8-B9 -> -223.6395 | C13: =C14-C7-C8-C9 -> -180.1328 | H13: =H14-H7-H8-H9 -> -95.4032 | I13: =0 -> 0 | J13: =0 -> 0 | K13: =0 -> 0 | L13: =0 -> 0 | M13: =SUM(I13:L13) -> 0 | N13: =0 -> 0 | O13: =0 -> 0 | P13: =0 -> 0 | Q13: =0 -> 0 | R13: =SUM(N13:Q13) -> 0 | S13: =0 -> 0 | T13: =0 -> 0 | U13: =0 -> 0 | V13: =0 -> 0 | W13: =SUM(S13:V13) -> 0
A14: 经营活动现金流 CFO | B14: 1144.4864 | C14: 1431.1862 | H14: 1698.9998 | I14: =SUM(I7:I13) -> 376.98075 | J14: =SUM(J7:J13) -> -237.81453 | K14: =SUM(K7:K13) -> 344.25181 | L14: =SUM(L7:L13) -> 562.65054 | M14: =SUM(I14:L14) -> 1046.0686 | N14: =SUM(N7:N13) -> 625.57005 | O14: =SUM(O7:O13) -> -23.956778 | P14: =SUM(P7:P13) -> 425.22145 | Q14: =SUM(Q7:Q13) -> 638.45086 | R14: =SUM(N14:Q14) -> 1665.2856 | S14: =SUM(S7:S13) -> 847.73423 | T14: =SUM(T7:T13) -> 44.826062 | U14: =SUM(U7:U13) -> 531.55689 | V14: =SUM(V7:V13) -> 721.93892 | W14: =SUM(S14:V14) -> 2146.0561
A15: 投资活动
A16: (−) 资本开支 | B16: -1100.8289 | C16: -818.9141 | H16: -728.9701 | I16: =-Drivers!I50 -> -340 | J16: =-Drivers!J50 -> -380 | K16: =-Drivers!K50 -> -390 | L16: =-Drivers!L50 -> -390 | M16: =SUM(I16:L16) -> -1500 | N16: =-Drivers!N50 -> -350 | O16: =-Drivers!O50 -> -345 | P16: =-Drivers!P50 -> -340 | Q16: =-Drivers!Q50 -> -325 | R16: =SUM(N16:Q16) -> -1360 | S16: =-Drivers!S50 -> -310 | T16: =-Drivers!T50 -> -305 | U16: =-Drivers!U50 -> -300 | V16: =-Drivers!V50 -> -285 | W16: =SUM(S16:V16) -> -1200
A17: (−) 长期投资及其他 | B17: -73.9527 | C17: -46.4014 | H17: 6.4142 | I17: =0 -> 0 | J17: =0 -> 0 | K17: =0 -> 0 | L17: =0 -> 0 | M17: =SUM(I17:L17) -> 0 | N17: =0 -> 0 | O17: =0 -> 0 | P17: =0 -> 0 | Q17: =0 -> 0 | R17: =SUM(N17:Q17) -> 0 | S17: =0 -> 0 | T17: =0 -> 0 | U17: =0 -> 0 | V17: =0 -> 0 | W17: =SUM(S17:V17) -> 0
A18: 投资活动现金流 CFI | B18: =B16+B17 -> -1174.7816 | C18: =C16+C17 -> -865.3155 | H18: =H16+H17 -> -722.5559 | I18: =I16+I17 -> -340 | J18: =J16+J17 -> -380 | K18: =K16+K17 -> -390 | L18: =L16+L17 -> -390 | M18: =SUM(I18:L18) -> -1500 | N18: =N16+N17 -> -350 | O18: =O16+O17 -> -345 | P18: =P16+P17 -> -340 | Q18: =Q16+Q17 -> -325 | R18: =SUM(N18:Q18) -> -1360 | S18: =S16+S17 -> -310 | T18: =T16+T17 -> -305 | U18: =U16+U17 -> -300 | V18: =V16+V17 -> -285 | W18: =SUM(S18:V18) -> -1200
A19: 筹资活动
A20: 吸收投资(含少数股东) | B20: 60.2355 | C20: 85.2669 | H20: 27.66235 | I20: =0 -> 0 | J20: =0 -> 0 | K20: =0 -> 0 | L20: =0 -> 0 | M20: =SUM(I20:L20) -> 0 | N20: =0 -> 0 | O20: =0 -> 0 | P20: =0 -> 0 | Q20: =0 -> 0 | R20: =SUM(N20:Q20) -> 0 | S20: =0 -> 0 | T20: =0 -> 0 | U20: =0 -> 0 | V20: =0 -> 0 | W20: =SUM(S20:V20) -> 0
A21: 借款净变动 | B21: 741.112 | C21: -480.3272 | H21: -147.3901 | I21: =Drivers!I56 -> 300 | J21: =Drivers!J56 -> 350 | K21: =Drivers!K56 -> 350 | L21: =Drivers!L56 -> 100 | M21: =SUM(I21:L21) -> 1100 | N21: =Drivers!N56 -> 200 | O21: =Drivers!O56 -> 200 | P21: =Drivers!P56 -> 200 | Q21: =Drivers!Q56 -> 200 | R21: =SUM(N21:Q21) -> 800 | S21: =Drivers!S56 -> 150 | T21: =Drivers!T56 -> 150 | U21: =Drivers!U56 -> 150 | V21: =Drivers!V56 -> 150 | W21: =SUM(S21:V21) -> 600
A22: 股利/利息支付(实际列·Wind口径) | B22: -293.4622 | C22: -390.7469 | H22: -627.0731 | M22: =SUM(I22:L22) -> 0 | R22: =SUM(N22:Q22) -> 0 | W22: =SUM(S22:V22) -> 0
A23: (−) 归母股利(预测,Q3支付上年宣告) | I23: =0 -> 0 | J23: =0 -> 0 | K23: =-Drivers!H62*Drivers!H61 -> -645.05472 | L23: =0 -> 0 | M23: =SUM(I23:L23) -> -645.05472 | N23: =0 -> 0 | O23: =0 -> 0 | P23: =-Drivers!M62*Drivers!M61 -> -663.28343 | Q23: =0 -> 0 | R23: =SUM(N23:Q23) -> -663.28343 | S23: =0 -> 0 | T23: =0 -> 0 | U23: =-Drivers!R62*Drivers!R61 -> -991.09054 | V23: =0 -> 0 | W23: =SUM(S23:V23) -> -991.09054
A24: (−) 少数股东股利(预测) ◀假设 | I24: =0 -> 0 | J24: =0 -> 0 | K24: -55 | L24: =0 -> 0 | M24: =SUM(I24:L24) -> -55 | N24: =0 -> 0 | O24: =0 -> 0 | P24: -55 | Q24: =0 -> 0 | R24: =SUM(N24:Q24) -> -55 | S24: =0 -> 0 | T24: =0 -> 0 | U24: -55 | V24: =0 -> 0 | W24: =SUM(S24:V24) -> -55
A25: 其他筹资净额 | B25: -161.5987 | C25: -256.9127 | H25: -172.7477 | I25: =0 -> 0 | J25: =0 -> 0 | K25: =0 -> 0 | L25: =0 -> 0 | M25: =SUM(I25:L25) -> 0 | N25: =0 -> 0 | O25: =0 -> 0 | P25: =0 -> 0 | Q25: =0 -> 0 | R25: =SUM(N25:Q25) -> 0 | S25: =0 -> 0 | T25: =0 -> 0 | U25: =0 -> 0 | V25: =0 -> 0 | W25: =SUM(S25:V25) -> 0
A26: 筹资活动现金流 CFF | B26: =SUM(B20:B25) -> 346.2866 | C26: =SUM(C20:C25) -> -1042.7199 | H26: =SUM(H20:H25) -> -919.54855 | I26: =SUM(I20:I25) -> 300 | J26: =SUM(J20:J25) -> 350 | K26: =SUM(K20:K25) -> -350.05472 | L26: =SUM(L20:L25) -> 100 | M26: =SUM(I26:L26) -> 399.94528 | N26: =SUM(N20:N25) -> 200 | O26: =SUM(O20:O25) -> 200 | P26: =SUM(P20:P25) -> -518.28343 | Q26: =SUM(Q20:Q25) -> 200 | R26: =SUM(N26:Q26) -> 81.71657 | S26: =SUM(S20:S25) -> 150 | T26: =SUM(T20:T25) -> 150 | U26: =SUM(U20:U25) -> -896.09054 | V26: =SUM(V20:V25) -> 150 | W26: =SUM(S26:V26) -> -446.09054
A27: 现金汇总
A28: 汇率影响 | B28: 3.7135 | C28: 6.1895 | H28: 3.8421 | I28: =0 -> 0 | J28: =0 -> 0 | K28: =0 -> 0 | L28: =0 -> 0 | M28: =SUM(I28:L28) -> 0 | N28: =0 -> 0 | O28: =0 -> 0 | P28: =0 -> 0 | Q28: =0 -> 0 | R28: =SUM(N28:Q28) -> 0 | S28: =0 -> 0 | T28: =0 -> 0 | U28: =0 -> 0 | V28: =0 -> 0 | W28: =SUM(S28:V28) -> 0
A29: 现金净变动 | B29: =B14+B18+B26+B28 -> 319.7049 | C29: =C14+C18+C26+C28 -> -470.6597 | H29: =H14+H18+H26+H28 -> 60.73745 | I29: =I14+I18+I26+I28 -> 336.98075 | J29: =J14+J18+J26+J28 -> -267.81453 | K29: =K14+K18+K26+K28 -> -395.80291 | L29: =L14+L18+L26+L28 -> 272.65054 | M29: =SUM(I29:L29) -> -53.986143 | N29: =N14+N18+N26+N28 -> 475.57005 | O29: =O14+O18+O26+O28 -> -168.95678 | P29: =P14+P18+P26+P28 -> -433.06198 | Q29: =Q14+Q18+Q26+Q28 -> 513.45086 | R29: =SUM(N29:Q29) -> 387.00215 | S29: =S14+S18+S26+S28 -> 687.73423 | T29: =T14+T18+T26+T28 -> -110.17394 | U29: =U14+U18+U26+U28 -> -664.53366 | V29: =V14+V18+V26+V28 -> 586.93892 | W29: =SUM(S29:V29) -> 499.96556
A30: 期初现金及等价物 | B30: 440.1894 | C30: 759.8944 | H30: 289.2348 | I30: =H31 -> 349.9723 | J30: =I31 -> 686.95305 | K30: =J31 -> 419.13852 | L30: =K31 -> 23.335613 | M30: =I30 -> 349.9723 | N30: =L31 -> 295.98616 | O30: =N31 -> 771.55621 | P30: =O31 -> 602.59943 | Q30: =P31 -> 169.53745 | R30: =N30 -> 295.98616 | S30: =Q31 -> 682.98831 | T30: =S31 -> 1370.7225 | U30: =T31 -> 1260.5486 | V30: =U31 -> 596.01495 | W30: =S30 -> 682.98831
A31: 期末现金及等价物 | B31: 759.8944 | C31: 289.2348 | H31: 349.9723 | I31: =I30+I29 -> 686.95305 | J31: =J30+J29 -> 419.13852 | K31: =K30+K29 -> 23.335613 | L31: =L30+L29 -> 295.98616 | M31: =L31 -> 295.98616 | N31: =N30+N29 -> 771.55621 | O31: =O30+O29 -> 602.59943 | P31: =P30+P29 -> 169.53745 | Q31: =Q30+Q29 -> 682.98831 | R31: =Q31 -> 682.98831 | S31: =S30+S29 -> 1370.7225 | T31: =T30+T29 -> 1260.5486 | U31: =U30+U29 -> 596.01495 | V31: =V30+V29 -> 1182.9539 | W31: =V31 -> 1182.9539
A33: Memo: FCF (CFO−Capex) | B33: =B14+B16 -> 43.6575 | C33: =C14+C16 -> 612.2721 | H33: =H14+H16 -> 970.0297 | I33: =I14+I16 -> 36.980754 | J33: =J14+J16 -> -617.81453 | K33: =K14+K16 -> -45.748186 | L33: =L14+L16 -> 172.65054 | M33: =SUM(I33:L33) -> -453.93142 | N33: =N14+N16 -> 275.57005 | O33: =O14+O16 -> -368.95678 | P33: =P14+P16 -> 85.221452 | Q33: =Q14+Q16 -> 313.45086 | R33: =SUM(N33:Q33) -> 305.28558 | S33: =S14+S16 -> 537.73423 | T33: =T14+T16 -> -260.17394 | U33: =U14+U16 -> 231.55689 | V33: =V14+V16 -> 436.93892 | W33: =SUM(S33:V33) -> 946.0561

Sheet Valuation
B2: 顺络电子 (002138.SZ) 目标价 — FY2027E P/E 概率加权
B3: Probability-Weighted Valuation | 倍数锚: 国信30-32x / 中金TP50元隐含23.7x 27E / 国巨链23-35x / A股被动件可比2026E中位~21x
C5: Bull | D5: Base | E5: Bear | F5: 加权
B6: 概率 | C6: 0.25 | D6: 0.55 | E6: 0.2 | F6: =SUM(C6:E6) -> 1 | G6: 对齐QPM 08_Scenarios: Bull25/Base55/Bear15+Tail5(并入Bear)
B8: 目标 P/E (FY2027E) | C8: 35 | D8: 30 | E8: 24 | G8: QPM情景PE: Bull35/Base30/Bear25/Tail20(2H27 Decel-Up期PE已打折);Bear=0.15×25x+0.05×20x≈24x
B9: 归母净利情景系数 (×Base) | C9: 1.25 | D9: 1 | E9: 0.7 | G9: QPM NP27E: Bull20.7/Base16.5/Bear12.4/Tail9.3亿→系数1.25/1.00/0.70(Bear+Tail加权);Bull=钽存储订单+NV提前+涨价25%全落地
